2019-12-01 base.py[line:93] Not Found: /favicon.ico
2019-12-01 base.py[line:93] Not Found: /favicon.ico
2020-01-03 base.py[line:93] Not Found: /favicon.ico
2020-01-05 base.py[line:93] Not Found: /favicon.ico
2020-01-05 exception.py[line:118] Internal Server Error: /admin/SignIn/user/1/permissions/
Traceback (most recent call last):
  File "C:\Users\heeeepin\Desktop\TiebaProject\venv\lib\site-packages\django\db\backends\utils.py", line 85, in _execute
    return self.cursor.execute(sql, params)
  File "C:\Users\heeeepin\Desktop\TiebaProject\venv\lib\site-packages\django\db\backends\mysql\base.py", line 71, in execute
    return self.cursor.execute(query, args)
  File "C:\Users\heeeepin\Desktop\TiebaProject\venv\lib\site-packages\pymysql\cursors.py", line 170, in execute
    result = self._query(query)
  File "C:\Users\heeeepin\Desktop\TiebaProject\venv\lib\site-packages\pymysql\cursors.py", line 328, in _query
    conn.query(q)
  File "C:\Users\heeeepin\Desktop\TiebaProject\venv\lib\site-packages\pymysql\connections.py", line 517, in query
    self._affected_rows = self._read_query_result(unbuffered=unbuffered)
  File "C:\Users\heeeepin\Desktop\TiebaProject\venv\lib\site-packages\pymysql\connections.py", line 732, in _read_query_result
    result.read()
  File "C:\Users\heeeepin\Desktop\TiebaProject\venv\lib\site-packages\pymysql\connections.py", line 1075, in read
    first_packet = self.connection._read_packet()
  File "C:\Users\heeeepin\Desktop\TiebaProject\venv\lib\site-packages\pymysql\connections.py", line 684, in _read_packet
    packet.check_error()
  File "C:\Users\heeeepin\Desktop\TiebaProject\venv\lib\site-packages\pymysql\protocol.py", line 220, in check_error
    err.raise_mysql_exception(self._data)
  File "C:\Users\heeeepin\Desktop\TiebaProject\venv\lib\site-packages\pymysql\err.py", line 109, in raise_mysql_exception
    raise errorclass(errno, errval)
pymysql.err.ProgrammingError: (1146, "Table 'tiebaproject.guardian_userobjectpermission' doesn't exist")

The above exception was the direct cause of the following exception:

Traceback (most recent call last):
  File "C:\Users\heeeepin\Desktop\TiebaProject\venv\lib\site-packages\django\core\handlers\exception.py", line 35, in inner
    response = get_response(request)
  File "C:\Users\heeeepin\Desktop\TiebaProject\venv\lib\site-packages\django\core\handlers\base.py", line 128, in _get_response
    response = self.process_exception_by_middleware(e, request)
  File "C:\Users\heeeepin\Desktop\TiebaProject\venv\lib\site-packages\django\core\handlers\base.py", line 126, in _get_response
    response = wrapped_callback(request, *callback_args, **callback_kwargs)
  File "C:\Users\heeeepin\Desktop\TiebaProject\venv\lib\site-packages\django\utils\decorators.py", line 142, in _wrapped_view
    response = view_func(request, *args, **kwargs)
  File "C:\Users\heeeepin\Desktop\TiebaProject\venv\lib\site-packages\django\views\decorators\cache.py", line 44, in _wrapped_view_func
    response = view_func(request, *args, **kwargs)
  File "C:\Users\heeeepin\Desktop\TiebaProject\venv\lib\site-packages\django\contrib\admin\sites.py", line 223, in inner
    return view(request, *args, **kwargs)
  File "C:\Users\heeeepin\Desktop\TiebaProject\venv\lib\site-packages\guardian\admin.py", line 146, in obj_perms_manage_view
    with_group_users=False).items(),
  File "C:\Users\heeeepin\Desktop\TiebaProject\venv\lib\site-packages\guardian\shortcuts.py", line 311, in get_users_with_perms
    with_superusers=with_superusers):
  File "C:\Users\heeeepin\Desktop\TiebaProject\venv\lib\site-packages\django\db\models\query.py", line 272, in __iter__
    self._fetch_all()
  File "C:\Users\heeeepin\Desktop\TiebaProject\venv\lib\site-packages\django\db\models\query.py", line 1179, in _fetch_all
    self._result_cache = list(self._iterable_class(self))
  File "C:\Users\heeeepin\Desktop\TiebaProject\venv\lib\site-packages\django\db\models\query.py", line 53, in __iter__
    results = compiler.execute_sql(chunked_fetch=self.chunked_fetch, chunk_size=self.chunk_size)
  File "C:\Users\heeeepin\Desktop\TiebaProject\venv\lib\site-packages\django\db\models\sql\compiler.py", line 1068, in execute_sql
    cursor.execute(sql, params)
  File "C:\Users\heeeepin\Desktop\TiebaProject\venv\lib\site-packages\django\db\backends\utils.py", line 100, in execute
    return super().execute(sql, params)
  File "C:\Users\heeeepin\Desktop\TiebaProject\venv\lib\site-packages\django\db\backends\utils.py", line 68, in execute
    return self._execute_with_wrappers(sql, params, many=False, executor=self._execute)
  File "C:\Users\heeeepin\Desktop\TiebaProject\venv\lib\site-packages\django\db\backends\utils.py", line 77, in _execute_with_wrappers
    return executor(sql, params, many, context)
  File "C:\Users\heeeepin\Desktop\TiebaProject\venv\lib\site-packages\django\db\backends\utils.py", line 85, in _execute
    return self.cursor.execute(sql, params)
  File "C:\Users\heeeepin\Desktop\TiebaProject\venv\lib\site-packages\django\db\utils.py", line 89, in __exit__
    raise dj_exc_value.with_traceback(traceback) from exc_value
  File "C:\Users\heeeepin\Desktop\TiebaProject\venv\lib\site-packages\django\db\backends\utils.py", line 85, in _execute
    return self.cursor.execute(sql, params)
  File "C:\Users\heeeepin\Desktop\TiebaProject\venv\lib\site-packages\django\db\backends\mysql\base.py", line 71, in execute
    return self.cursor.execute(query, args)
  File "C:\Users\heeeepin\Desktop\TiebaProject\venv\lib\site-packages\pymysql\cursors.py", line 170, in execute
    result = self._query(query)
  File "C:\Users\heeeepin\Desktop\TiebaProject\venv\lib\site-packages\pymysql\cursors.py", line 328, in _query
    conn.query(q)
  File "C:\Users\heeeepin\Desktop\TiebaProject\venv\lib\site-packages\pymysql\connections.py", line 517, in query
    self._affected_rows = self._read_query_result(unbuffered=unbuffered)
  File "C:\Users\heeeepin\Desktop\TiebaProject\venv\lib\site-packages\pymysql\connections.py", line 732, in _read_query_result
    result.read()
  File "C:\Users\heeeepin\Desktop\TiebaProject\venv\lib\site-packages\pymysql\connections.py", line 1075, in read
    first_packet = self.connection._read_packet()
  File "C:\Users\heeeepin\Desktop\TiebaProject\venv\lib\site-packages\pymysql\connections.py", line 684, in _read_packet
    packet.check_error()
  File "C:\Users\heeeepin\Desktop\TiebaProject\venv\lib\site-packages\pymysql\protocol.py", line 220, in check_error
    err.raise_mysql_exception(self._data)
  File "C:\Users\heeeepin\Desktop\TiebaProject\venv\lib\site-packages\pymysql\err.py", line 109, in raise_mysql_exception
    raise errorclass(errno, errval)
django.db.utils.ProgrammingError: (1146, "Table 'tiebaproject.guardian_userobjectpermission' doesn't exist")
2020-01-05 exception.py[line:118] Internal Server Error: /admin/SignIn/user/1/permissions/
Traceback (most recent call last):
  File "C:\Users\heeeepin\Desktop\TiebaProject\venv\lib\site-packages\django\db\backends\utils.py", line 85, in _execute
    return self.cursor.execute(sql, params)
  File "C:\Users\heeeepin\Desktop\TiebaProject\venv\lib\site-packages\django\db\backends\mysql\base.py", line 71, in execute
    return self.cursor.execute(query, args)
  File "C:\Users\heeeepin\Desktop\TiebaProject\venv\lib\site-packages\pymysql\cursors.py", line 170, in execute
    result = self._query(query)
  File "C:\Users\heeeepin\Desktop\TiebaProject\venv\lib\site-packages\pymysql\cursors.py", line 328, in _query
    conn.query(q)
  File "C:\Users\heeeepin\Desktop\TiebaProject\venv\lib\site-packages\pymysql\connections.py", line 517, in query
    self._affected_rows = self._read_query_result(unbuffered=unbuffered)
  File "C:\Users\heeeepin\Desktop\TiebaProject\venv\lib\site-packages\pymysql\connections.py", line 732, in _read_query_result
    result.read()
  File "C:\Users\heeeepin\Desktop\TiebaProject\venv\lib\site-packages\pymysql\connections.py", line 1075, in read
    first_packet = self.connection._read_packet()
  File "C:\Users\heeeepin\Desktop\TiebaProject\venv\lib\site-packages\pymysql\connections.py", line 684, in _read_packet
    packet.check_error()
  File "C:\Users\heeeepin\Desktop\TiebaProject\venv\lib\site-packages\pymysql\protocol.py", line 220, in check_error
    err.raise_mysql_exception(self._data)
  File "C:\Users\heeeepin\Desktop\TiebaProject\venv\lib\site-packages\pymysql\err.py", line 109, in raise_mysql_exception
    raise errorclass(errno, errval)
pymysql.err.ProgrammingError: (1146, "Table 'tiebaproject.guardian_userobjectpermission' doesn't exist")

The above exception was the direct cause of the following exception:

Traceback (most recent call last):
  File "C:\Users\heeeepin\Desktop\TiebaProject\venv\lib\site-packages\django\core\handlers\exception.py", line 35, in inner
    response = get_response(request)
  File "C:\Users\heeeepin\Desktop\TiebaProject\venv\lib\site-packages\django\core\handlers\base.py", line 128, in _get_response
    response = self.process_exception_by_middleware(e, request)
  File "C:\Users\heeeepin\Desktop\TiebaProject\venv\lib\site-packages\django\core\handlers\base.py", line 126, in _get_response
    response = wrapped_callback(request, *callback_args, **callback_kwargs)
  File "C:\Users\heeeepin\Desktop\TiebaProject\venv\lib\site-packages\django\utils\decorators.py", line 142, in _wrapped_view
    response = view_func(request, *args, **kwargs)
  File "C:\Users\heeeepin\Desktop\TiebaProject\venv\lib\site-packages\django\views\decorators\cache.py", line 44, in _wrapped_view_func
    response = view_func(request, *args, **kwargs)
  File "C:\Users\heeeepin\Desktop\TiebaProject\venv\lib\site-packages\django\contrib\admin\sites.py", line 223, in inner
    return view(request, *args, **kwargs)
  File "C:\Users\heeeepin\Desktop\TiebaProject\venv\lib\site-packages\guardian\admin.py", line 146, in obj_perms_manage_view
    with_group_users=False).items(),
  File "C:\Users\heeeepin\Desktop\TiebaProject\venv\lib\site-packages\guardian\shortcuts.py", line 311, in get_users_with_perms
    with_superusers=with_superusers):
  File "C:\Users\heeeepin\Desktop\TiebaProject\venv\lib\site-packages\django\db\models\query.py", line 272, in __iter__
    self._fetch_all()
  File "C:\Users\heeeepin\Desktop\TiebaProject\venv\lib\site-packages\django\db\models\query.py", line 1179, in _fetch_all
    self._result_cache = list(self._iterable_class(self))
  File "C:\Users\heeeepin\Desktop\TiebaProject\venv\lib\site-packages\django\db\models\query.py", line 53, in __iter__
    results = compiler.execute_sql(chunked_fetch=self.chunked_fetch, chunk_size=self.chunk_size)
  File "C:\Users\heeeepin\Desktop\TiebaProject\venv\lib\site-packages\django\db\models\sql\compiler.py", line 1068, in execute_sql
    cursor.execute(sql, params)
  File "C:\Users\heeeepin\Desktop\TiebaProject\venv\lib\site-packages\django\db\backends\utils.py", line 100, in execute
    return super().execute(sql, params)
  File "C:\Users\heeeepin\Desktop\TiebaProject\venv\lib\site-packages\django\db\backends\utils.py", line 68, in execute
    return self._execute_with_wrappers(sql, params, many=False, executor=self._execute)
  File "C:\Users\heeeepin\Desktop\TiebaProject\venv\lib\site-packages\django\db\backends\utils.py", line 77, in _execute_with_wrappers
    return executor(sql, params, many, context)
  File "C:\Users\heeeepin\Desktop\TiebaProject\venv\lib\site-packages\django\db\backends\utils.py", line 85, in _execute
    return self.cursor.execute(sql, params)
  File "C:\Users\heeeepin\Desktop\TiebaProject\venv\lib\site-packages\django\db\utils.py", line 89, in __exit__
    raise dj_exc_value.with_traceback(traceback) from exc_value
  File "C:\Users\heeeepin\Desktop\TiebaProject\venv\lib\site-packages\django\db\backends\utils.py", line 85, in _execute
    return self.cursor.execute(sql, params)
  File "C:\Users\heeeepin\Desktop\TiebaProject\venv\lib\site-packages\django\db\backends\mysql\base.py", line 71, in execute
    return self.cursor.execute(query, args)
  File "C:\Users\heeeepin\Desktop\TiebaProject\venv\lib\site-packages\pymysql\cursors.py", line 170, in execute
    result = self._query(query)
  File "C:\Users\heeeepin\Desktop\TiebaProject\venv\lib\site-packages\pymysql\cursors.py", line 328, in _query
    conn.query(q)
  File "C:\Users\heeeepin\Desktop\TiebaProject\venv\lib\site-packages\pymysql\connections.py", line 517, in query
    self._affected_rows = self._read_query_result(unbuffered=unbuffered)
  File "C:\Users\heeeepin\Desktop\TiebaProject\venv\lib\site-packages\pymysql\connections.py", line 732, in _read_query_result
    result.read()
  File "C:\Users\heeeepin\Desktop\TiebaProject\venv\lib\site-packages\pymysql\connections.py", line 1075, in read
    first_packet = self.connection._read_packet()
  File "C:\Users\heeeepin\Desktop\TiebaProject\venv\lib\site-packages\pymysql\connections.py", line 684, in _read_packet
    packet.check_error()
  File "C:\Users\heeeepin\Desktop\TiebaProject\venv\lib\site-packages\pymysql\protocol.py", line 220, in check_error
    err.raise_mysql_exception(self._data)
  File "C:\Users\heeeepin\Desktop\TiebaProject\venv\lib\site-packages\pymysql\err.py", line 109, in raise_mysql_exception
    raise errorclass(errno, errval)
django.db.utils.ProgrammingError: (1146, "Table 'tiebaproject.guardian_userobjectpermission' doesn't exist")
2020-01-05 log.py[line:228] Internal Server Error: /admin/auth/group/add/
Traceback (most recent call last):
  File "C:\Users\heeeepin\Desktop\TiebaProject\venv\lib\site-packages\django\contrib\sessions\backends\base.py", line 190, in _get_session
    return self._session_cache
AttributeError: 'SessionStore' object has no attribute '_session_cache'

During handling of the above exception, another exception occurred:

Traceback (most recent call last):
  File "C:\Users\heeeepin\Desktop\TiebaProject\venv\lib\site-packages\django\db\backends\utils.py", line 85, in _execute
    return self.cursor.execute(sql, params)
  File "C:\Users\heeeepin\Desktop\TiebaProject\venv\lib\site-packages\django\db\backends\mysql\base.py", line 71, in execute
    return self.cursor.execute(query, args)
  File "C:\Users\heeeepin\Desktop\TiebaProject\venv\lib\site-packages\pymysql\cursors.py", line 170, in execute
    result = self._query(query)
  File "C:\Users\heeeepin\Desktop\TiebaProject\venv\lib\site-packages\pymysql\cursors.py", line 328, in _query
    conn.query(q)
  File "C:\Users\heeeepin\Desktop\TiebaProject\venv\lib\site-packages\pymysql\connections.py", line 517, in query
    self._affected_rows = self._read_query_result(unbuffered=unbuffered)
  File "C:\Users\heeeepin\Desktop\TiebaProject\venv\lib\site-packages\pymysql\connections.py", line 732, in _read_query_result
    result.read()
  File "C:\Users\heeeepin\Desktop\TiebaProject\venv\lib\site-packages\pymysql\connections.py", line 1075, in read
    first_packet = self.connection._read_packet()
  File "C:\Users\heeeepin\Desktop\TiebaProject\venv\lib\site-packages\pymysql\connections.py", line 684, in _read_packet
    packet.check_error()
  File "C:\Users\heeeepin\Desktop\TiebaProject\venv\lib\site-packages\pymysql\protocol.py", line 220, in check_error
    err.raise_mysql_exception(self._data)
  File "C:\Users\heeeepin\Desktop\TiebaProject\venv\lib\site-packages\pymysql\err.py", line 109, in raise_mysql_exception
    raise errorclass(errno, errval)
pymysql.err.ProgrammingError: (1146, "Table 'tiebaproject.django_session' doesn't exist")

The above exception was the direct cause of the following exception:

Traceback (most recent call last):
  File "C:\Users\heeeepin\Desktop\TiebaProject\venv\lib\site-packages\django\core\handlers\exception.py", line 34, in inner
    response = get_response(request)
  File "C:\Users\heeeepin\Desktop\TiebaProject\venv\lib\site-packages\django\core\handlers\base.py", line 126, in _get_response
    response = self.process_exception_by_middleware(e, request)
  File "C:\Users\heeeepin\Desktop\TiebaProject\venv\lib\site-packages\django\core\handlers\base.py", line 124, in _get_response
    response = wrapped_callback(request, *callback_args, **callback_kwargs)
  File "C:\Users\heeeepin\Desktop\TiebaProject\venv\lib\site-packages\django\contrib\admin\options.py", line 604, in wrapper
    return self.admin_site.admin_view(view)(*args, **kwargs)
  File "C:\Users\heeeepin\Desktop\TiebaProject\venv\lib\site-packages\django\utils\decorators.py", line 142, in _wrapped_view
    response = view_func(request, *args, **kwargs)
  File "C:\Users\heeeepin\Desktop\TiebaProject\venv\lib\site-packages\django\views\decorators\cache.py", line 44, in _wrapped_view_func
    response = view_func(request, *args, **kwargs)
  File "C:\Users\heeeepin\Desktop\TiebaProject\venv\lib\site-packages\django\contrib\admin\sites.py", line 212, in inner
    if not self.has_permission(request):
  File "C:\Users\heeeepin\Desktop\TiebaProject\venv\lib\site-packages\django\contrib\admin\sites.py", line 186, in has_permission
    return request.user.is_active and request.user.is_staff
  File "C:\Users\heeeepin\Desktop\TiebaProject\venv\lib\site-packages\django\utils\functional.py", line 213, in inner
    self._setup()
  File "C:\Users\heeeepin\Desktop\TiebaProject\venv\lib\site-packages\django\utils\functional.py", line 347, in _setup
    self._wrapped = self._setupfunc()
  File "C:\Users\heeeepin\Desktop\TiebaProject\venv\lib\site-packages\django\contrib\auth\middleware.py", line 24, in <lambda>
    request.user = SimpleLazyObject(lambda: get_user(request))
  File "C:\Users\heeeepin\Desktop\TiebaProject\venv\lib\site-packages\django\contrib\auth\middleware.py", line 12, in get_user
    request._cached_user = auth.get_user(request)
  File "C:\Users\heeeepin\Desktop\TiebaProject\venv\lib\site-packages\django\contrib\auth\__init__.py", line 182, in get_user
    user_id = _get_user_session_key(request)
  File "C:\Users\heeeepin\Desktop\TiebaProject\venv\lib\site-packages\django\contrib\auth\__init__.py", line 59, in _get_user_session_key
    return get_user_model()._meta.pk.to_python(request.session[SESSION_KEY])
  File "C:\Users\heeeepin\Desktop\TiebaProject\venv\lib\site-packages\django\contrib\sessions\backends\base.py", line 55, in __getitem__
    return self._session[key]
  File "C:\Users\heeeepin\Desktop\TiebaProject\venv\lib\site-packages\django\contrib\sessions\backends\base.py", line 195, in _get_session
    self._session_cache = self.load()
  File "C:\Users\heeeepin\Desktop\TiebaProject\venv\lib\site-packages\django\contrib\sessions\backends\db.py", line 43, in load
    s = self._get_session_from_db()
  File "C:\Users\heeeepin\Desktop\TiebaProject\venv\lib\site-packages\django\contrib\sessions\backends\db.py", line 34, in _get_session_from_db
    expire_date__gt=timezone.now()
  File "C:\Users\heeeepin\Desktop\TiebaProject\venv\lib\site-packages\django\db\models\manager.py", line 82, in manager_method
    return getattr(self.get_queryset(), name)(*args, **kwargs)
  File "C:\Users\heeeepin\Desktop\TiebaProject\venv\lib\site-packages\django\db\models\query.py", line 393, in get
    num = len(clone)
  File "C:\Users\heeeepin\Desktop\TiebaProject\venv\lib\site-packages\django\db\models\query.py", line 250, in __len__
    self._fetch_all()
  File "C:\Users\heeeepin\Desktop\TiebaProject\venv\lib\site-packages\django\db\models\query.py", line 1186, in _fetch_all
    self._result_cache = list(self._iterable_class(self))
  File "C:\Users\heeeepin\Desktop\TiebaProject\venv\lib\site-packages\django\db\models\query.py", line 54, in __iter__
    results = compiler.execute_sql(chunked_fetch=self.chunked_fetch, chunk_size=self.chunk_size)
  File "C:\Users\heeeepin\Desktop\TiebaProject\venv\lib\site-packages\django\db\models\sql\compiler.py", line 1065, in execute_sql
    cursor.execute(sql, params)
  File "C:\Users\heeeepin\Desktop\TiebaProject\venv\lib\site-packages\django\db\backends\utils.py", line 100, in execute
    return super().execute(sql, params)
  File "C:\Users\heeeepin\Desktop\TiebaProject\venv\lib\site-packages\django\db\backends\utils.py", line 68, in execute
    return self._execute_with_wrappers(sql, params, many=False, executor=self._execute)
  File "C:\Users\heeeepin\Desktop\TiebaProject\venv\lib\site-packages\django\db\backends\utils.py", line 77, in _execute_with_wrappers
    return executor(sql, params, many, context)
  File "C:\Users\heeeepin\Desktop\TiebaProject\venv\lib\site-packages\django\db\backends\utils.py", line 85, in _execute
    return self.cursor.execute(sql, params)
  File "C:\Users\heeeepin\Desktop\TiebaProject\venv\lib\site-packages\django\db\utils.py", line 89, in __exit__
    raise dj_exc_value.with_traceback(traceback) from exc_value
  File "C:\Users\heeeepin\Desktop\TiebaProject\venv\lib\site-packages\django\db\backends\utils.py", line 85, in _execute
    return self.cursor.execute(sql, params)
  File "C:\Users\heeeepin\Desktop\TiebaProject\venv\lib\site-packages\django\db\backends\mysql\base.py", line 71, in execute
    return self.cursor.execute(query, args)
  File "C:\Users\heeeepin\Desktop\TiebaProject\venv\lib\site-packages\pymysql\cursors.py", line 170, in execute
    result = self._query(query)
  File "C:\Users\heeeepin\Desktop\TiebaProject\venv\lib\site-packages\pymysql\cursors.py", line 328, in _query
    conn.query(q)
  File "C:\Users\heeeepin\Desktop\TiebaProject\venv\lib\site-packages\pymysql\connections.py", line 517, in query
    self._affected_rows = self._read_query_result(unbuffered=unbuffered)
  File "C:\Users\heeeepin\Desktop\TiebaProject\venv\lib\site-packages\pymysql\connections.py", line 732, in _read_query_result
    result.read()
  File "C:\Users\heeeepin\Desktop\TiebaProject\venv\lib\site-packages\pymysql\connections.py", line 1075, in read
    first_packet = self.connection._read_packet()
  File "C:\Users\heeeepin\Desktop\TiebaProject\venv\lib\site-packages\pymysql\connections.py", line 684, in _read_packet
    packet.check_error()
  File "C:\Users\heeeepin\Desktop\TiebaProject\venv\lib\site-packages\pymysql\protocol.py", line 220, in check_error
    err.raise_mysql_exception(self._data)
  File "C:\Users\heeeepin\Desktop\TiebaProject\venv\lib\site-packages\pymysql\err.py", line 109, in raise_mysql_exception
    raise errorclass(errno, errval)
django.db.utils.ProgrammingError: (1146, "Table 'tiebaproject.django_session' doesn't exist")
2020-01-05 log.py[line:228] Internal Server Error: /admin/
Traceback (most recent call last):
  File "C:\Users\heeeepin\Desktop\TiebaProject\venv\lib\site-packages\django\contrib\sessions\backends\base.py", line 190, in _get_session
    return self._session_cache
AttributeError: 'SessionStore' object has no attribute '_session_cache'

During handling of the above exception, another exception occurred:

Traceback (most recent call last):
  File "C:\Users\heeeepin\Desktop\TiebaProject\venv\lib\site-packages\django\db\backends\utils.py", line 85, in _execute
    return self.cursor.execute(sql, params)
  File "C:\Users\heeeepin\Desktop\TiebaProject\venv\lib\site-packages\django\db\backends\mysql\base.py", line 71, in execute
    return self.cursor.execute(query, args)
  File "C:\Users\heeeepin\Desktop\TiebaProject\venv\lib\site-packages\pymysql\cursors.py", line 170, in execute
    result = self._query(query)
  File "C:\Users\heeeepin\Desktop\TiebaProject\venv\lib\site-packages\pymysql\cursors.py", line 328, in _query
    conn.query(q)
  File "C:\Users\heeeepin\Desktop\TiebaProject\venv\lib\site-packages\pymysql\connections.py", line 517, in query
    self._affected_rows = self._read_query_result(unbuffered=unbuffered)
  File "C:\Users\heeeepin\Desktop\TiebaProject\venv\lib\site-packages\pymysql\connections.py", line 732, in _read_query_result
    result.read()
  File "C:\Users\heeeepin\Desktop\TiebaProject\venv\lib\site-packages\pymysql\connections.py", line 1075, in read
    first_packet = self.connection._read_packet()
  File "C:\Users\heeeepin\Desktop\TiebaProject\venv\lib\site-packages\pymysql\connections.py", line 684, in _read_packet
    packet.check_error()
  File "C:\Users\heeeepin\Desktop\TiebaProject\venv\lib\site-packages\pymysql\protocol.py", line 220, in check_error
    err.raise_mysql_exception(self._data)
  File "C:\Users\heeeepin\Desktop\TiebaProject\venv\lib\site-packages\pymysql\err.py", line 109, in raise_mysql_exception
    raise errorclass(errno, errval)
pymysql.err.ProgrammingError: (1146, "Table 'tiebaproject.django_session' doesn't exist")

The above exception was the direct cause of the following exception:

Traceback (most recent call last):
  File "C:\Users\heeeepin\Desktop\TiebaProject\venv\lib\site-packages\django\core\handlers\exception.py", line 34, in inner
    response = get_response(request)
  File "C:\Users\heeeepin\Desktop\TiebaProject\venv\lib\site-packages\django\core\handlers\base.py", line 126, in _get_response
    response = self.process_exception_by_middleware(e, request)
  File "C:\Users\heeeepin\Desktop\TiebaProject\venv\lib\site-packages\django\core\handlers\base.py", line 124, in _get_response
    response = wrapped_callback(request, *callback_args, **callback_kwargs)
  File "C:\Users\heeeepin\Desktop\TiebaProject\venv\lib\site-packages\django\contrib\admin\sites.py", line 241, in wrapper
    return self.admin_view(view, cacheable)(*args, **kwargs)
  File "C:\Users\heeeepin\Desktop\TiebaProject\venv\lib\site-packages\django\utils\decorators.py", line 142, in _wrapped_view
    response = view_func(request, *args, **kwargs)
  File "C:\Users\heeeepin\Desktop\TiebaProject\venv\lib\site-packages\django\views\decorators\cache.py", line 44, in _wrapped_view_func
    response = view_func(request, *args, **kwargs)
  File "C:\Users\heeeepin\Desktop\TiebaProject\venv\lib\site-packages\django\contrib\admin\sites.py", line 212, in inner
    if not self.has_permission(request):
  File "C:\Users\heeeepin\Desktop\TiebaProject\venv\lib\site-packages\django\contrib\admin\sites.py", line 186, in has_permission
    return request.user.is_active and request.user.is_staff
  File "C:\Users\heeeepin\Desktop\TiebaProject\venv\lib\site-packages\django\utils\functional.py", line 213, in inner
    self._setup()
  File "C:\Users\heeeepin\Desktop\TiebaProject\venv\lib\site-packages\django\utils\functional.py", line 347, in _setup
    self._wrapped = self._setupfunc()
  File "C:\Users\heeeepin\Desktop\TiebaProject\venv\lib\site-packages\django\contrib\auth\middleware.py", line 24, in <lambda>
    request.user = SimpleLazyObject(lambda: get_user(request))
  File "C:\Users\heeeepin\Desktop\TiebaProject\venv\lib\site-packages\django\contrib\auth\middleware.py", line 12, in get_user
    request._cached_user = auth.get_user(request)
  File "C:\Users\heeeepin\Desktop\TiebaProject\venv\lib\site-packages\django\contrib\auth\__init__.py", line 182, in get_user
    user_id = _get_user_session_key(request)
  File "C:\Users\heeeepin\Desktop\TiebaProject\venv\lib\site-packages\django\contrib\auth\__init__.py", line 59, in _get_user_session_key
    return get_user_model()._meta.pk.to_python(request.session[SESSION_KEY])
  File "C:\Users\heeeepin\Desktop\TiebaProject\venv\lib\site-packages\django\contrib\sessions\backends\base.py", line 55, in __getitem__
    return self._session[key]
  File "C:\Users\heeeepin\Desktop\TiebaProject\venv\lib\site-packages\django\contrib\sessions\backends\base.py", line 195, in _get_session
    self._session_cache = self.load()
  File "C:\Users\heeeepin\Desktop\TiebaProject\venv\lib\site-packages\django\contrib\sessions\backends\db.py", line 43, in load
    s = self._get_session_from_db()
  File "C:\Users\heeeepin\Desktop\TiebaProject\venv\lib\site-packages\django\contrib\sessions\backends\db.py", line 34, in _get_session_from_db
    expire_date__gt=timezone.now()
  File "C:\Users\heeeepin\Desktop\TiebaProject\venv\lib\site-packages\django\db\models\manager.py", line 82, in manager_method
    return getattr(self.get_queryset(), name)(*args, **kwargs)
  File "C:\Users\heeeepin\Desktop\TiebaProject\venv\lib\site-packages\django\db\models\query.py", line 393, in get
    num = len(clone)
  File "C:\Users\heeeepin\Desktop\TiebaProject\venv\lib\site-packages\django\db\models\query.py", line 250, in __len__
    self._fetch_all()
  File "C:\Users\heeeepin\Desktop\TiebaProject\venv\lib\site-packages\django\db\models\query.py", line 1186, in _fetch_all
    self._result_cache = list(self._iterable_class(self))
  File "C:\Users\heeeepin\Desktop\TiebaProject\venv\lib\site-packages\django\db\models\query.py", line 54, in __iter__
    results = compiler.execute_sql(chunked_fetch=self.chunked_fetch, chunk_size=self.chunk_size)
  File "C:\Users\heeeepin\Desktop\TiebaProject\venv\lib\site-packages\django\db\models\sql\compiler.py", line 1065, in execute_sql
    cursor.execute(sql, params)
  File "C:\Users\heeeepin\Desktop\TiebaProject\venv\lib\site-packages\django\db\backends\utils.py", line 100, in execute
    return super().execute(sql, params)
  File "C:\Users\heeeepin\Desktop\TiebaProject\venv\lib\site-packages\django\db\backends\utils.py", line 68, in execute
    return self._execute_with_wrappers(sql, params, many=False, executor=self._execute)
  File "C:\Users\heeeepin\Desktop\TiebaProject\venv\lib\site-packages\django\db\backends\utils.py", line 77, in _execute_with_wrappers
    return executor(sql, params, many, context)
  File "C:\Users\heeeepin\Desktop\TiebaProject\venv\lib\site-packages\django\db\backends\utils.py", line 85, in _execute
    return self.cursor.execute(sql, params)
  File "C:\Users\heeeepin\Desktop\TiebaProject\venv\lib\site-packages\django\db\utils.py", line 89, in __exit__
    raise dj_exc_value.with_traceback(traceback) from exc_value
  File "C:\Users\heeeepin\Desktop\TiebaProject\venv\lib\site-packages\django\db\backends\utils.py", line 85, in _execute
    return self.cursor.execute(sql, params)
  File "C:\Users\heeeepin\Desktop\TiebaProject\venv\lib\site-packages\django\db\backends\mysql\base.py", line 71, in execute
    return self.cursor.execute(query, args)
  File "C:\Users\heeeepin\Desktop\TiebaProject\venv\lib\site-packages\pymysql\cursors.py", line 170, in execute
    result = self._query(query)
  File "C:\Users\heeeepin\Desktop\TiebaProject\venv\lib\site-packages\pymysql\cursors.py", line 328, in _query
    conn.query(q)
  File "C:\Users\heeeepin\Desktop\TiebaProject\venv\lib\site-packages\pymysql\connections.py", line 517, in query
    self._affected_rows = self._read_query_result(unbuffered=unbuffered)
  File "C:\Users\heeeepin\Desktop\TiebaProject\venv\lib\site-packages\pymysql\connections.py", line 732, in _read_query_result
    result.read()
  File "C:\Users\heeeepin\Desktop\TiebaProject\venv\lib\site-packages\pymysql\connections.py", line 1075, in read
    first_packet = self.connection._read_packet()
  File "C:\Users\heeeepin\Desktop\TiebaProject\venv\lib\site-packages\pymysql\connections.py", line 684, in _read_packet
    packet.check_error()
  File "C:\Users\heeeepin\Desktop\TiebaProject\venv\lib\site-packages\pymysql\protocol.py", line 220, in check_error
    err.raise_mysql_exception(self._data)
  File "C:\Users\heeeepin\Desktop\TiebaProject\venv\lib\site-packages\pymysql\err.py", line 109, in raise_mysql_exception
    raise errorclass(errno, errval)
django.db.utils.ProgrammingError: (1146, "Table 'tiebaproject.django_session' doesn't exist")
2020-01-05 log.py[line:228] Not Found: /favicon.ico
2020-01-05 log.py[line:228] Forbidden (Permission denied): /admin/auth/user/
Traceback (most recent call last):
  File "C:\Users\heeeepin\Desktop\TiebaProject\venv\lib\site-packages\django\core\handlers\exception.py", line 34, in inner
    response = get_response(request)
  File "C:\Users\heeeepin\Desktop\TiebaProject\venv\lib\site-packages\django\core\handlers\base.py", line 126, in _get_response
    response = self.process_exception_by_middleware(e, request)
  File "C:\Users\heeeepin\Desktop\TiebaProject\venv\lib\site-packages\django\core\handlers\base.py", line 124, in _get_response
    response = wrapped_callback(request, *callback_args, **callback_kwargs)
  File "C:\Users\heeeepin\Desktop\TiebaProject\venv\lib\site-packages\django\contrib\admin\options.py", line 604, in wrapper
    return self.admin_site.admin_view(view)(*args, **kwargs)
  File "C:\Users\heeeepin\Desktop\TiebaProject\venv\lib\site-packages\django\utils\decorators.py", line 142, in _wrapped_view
    response = view_func(request, *args, **kwargs)
  File "C:\Users\heeeepin\Desktop\TiebaProject\venv\lib\site-packages\django\views\decorators\cache.py", line 44, in _wrapped_view_func
    response = view_func(request, *args, **kwargs)
  File "C:\Users\heeeepin\Desktop\TiebaProject\venv\lib\site-packages\django\contrib\admin\sites.py", line 223, in inner
    return view(request, *args, **kwargs)
  File "C:\Users\heeeepin\Desktop\TiebaProject\venv\lib\site-packages\django\utils\decorators.py", line 45, in _wrapper
    return bound_method(*args, **kwargs)
  File "C:\Users\heeeepin\Desktop\TiebaProject\venv\lib\site-packages\django\utils\decorators.py", line 142, in _wrapped_view
    response = view_func(request, *args, **kwargs)
  File "C:\Users\heeeepin\Desktop\TiebaProject\venv\lib\site-packages\django\contrib\admin\options.py", line 1671, in changelist_view
    raise PermissionDenied
django.core.exceptions.PermissionDenied
2020-01-05 log.py[line:228] Forbidden (Permission denied): /admin/auth/user/
Traceback (most recent call last):
  File "C:\Users\heeeepin\Desktop\TiebaProject\venv\lib\site-packages\django\core\handlers\exception.py", line 34, in inner
    response = get_response(request)
  File "C:\Users\heeeepin\Desktop\TiebaProject\venv\lib\site-packages\django\core\handlers\base.py", line 126, in _get_response
    response = self.process_exception_by_middleware(e, request)
  File "C:\Users\heeeepin\Desktop\TiebaProject\venv\lib\site-packages\django\core\handlers\base.py", line 124, in _get_response
    response = wrapped_callback(request, *callback_args, **callback_kwargs)
  File "C:\Users\heeeepin\Desktop\TiebaProject\venv\lib\site-packages\django\contrib\admin\options.py", line 604, in wrapper
    return self.admin_site.admin_view(view)(*args, **kwargs)
  File "C:\Users\heeeepin\Desktop\TiebaProject\venv\lib\site-packages\django\utils\decorators.py", line 142, in _wrapped_view
    response = view_func(request, *args, **kwargs)
  File "C:\Users\heeeepin\Desktop\TiebaProject\venv\lib\site-packages\django\views\decorators\cache.py", line 44, in _wrapped_view_func
    response = view_func(request, *args, **kwargs)
  File "C:\Users\heeeepin\Desktop\TiebaProject\venv\lib\site-packages\django\contrib\admin\sites.py", line 223, in inner
    return view(request, *args, **kwargs)
  File "C:\Users\heeeepin\Desktop\TiebaProject\venv\lib\site-packages\django\utils\decorators.py", line 45, in _wrapper
    return bound_method(*args, **kwargs)
  File "C:\Users\heeeepin\Desktop\TiebaProject\venv\lib\site-packages\django\utils\decorators.py", line 142, in _wrapped_view
    response = view_func(request, *args, **kwargs)
  File "C:\Users\heeeepin\Desktop\TiebaProject\venv\lib\site-packages\django\contrib\admin\options.py", line 1671, in changelist_view
    raise PermissionDenied
django.core.exceptions.PermissionDenied
2020-01-05 log.py[line:228] Forbidden (Permission denied): /admin/auth/user/
Traceback (most recent call last):
  File "C:\Users\heeeepin\Desktop\TiebaProject\venv\lib\site-packages\django\core\handlers\exception.py", line 34, in inner
    response = get_response(request)
  File "C:\Users\heeeepin\Desktop\TiebaProject\venv\lib\site-packages\django\core\handlers\base.py", line 126, in _get_response
    response = self.process_exception_by_middleware(e, request)
  File "C:\Users\heeeepin\Desktop\TiebaProject\venv\lib\site-packages\django\core\handlers\base.py", line 124, in _get_response
    response = wrapped_callback(request, *callback_args, **callback_kwargs)
  File "C:\Users\heeeepin\Desktop\TiebaProject\venv\lib\site-packages\django\contrib\admin\options.py", line 604, in wrapper
    return self.admin_site.admin_view(view)(*args, **kwargs)
  File "C:\Users\heeeepin\Desktop\TiebaProject\venv\lib\site-packages\django\utils\decorators.py", line 142, in _wrapped_view
    response = view_func(request, *args, **kwargs)
  File "C:\Users\heeeepin\Desktop\TiebaProject\venv\lib\site-packages\django\views\decorators\cache.py", line 44, in _wrapped_view_func
    response = view_func(request, *args, **kwargs)
  File "C:\Users\heeeepin\Desktop\TiebaProject\venv\lib\site-packages\django\contrib\admin\sites.py", line 223, in inner
    return view(request, *args, **kwargs)
  File "C:\Users\heeeepin\Desktop\TiebaProject\venv\lib\site-packages\django\utils\decorators.py", line 45, in _wrapper
    return bound_method(*args, **kwargs)
  File "C:\Users\heeeepin\Desktop\TiebaProject\venv\lib\site-packages\django\utils\decorators.py", line 142, in _wrapped_view
    response = view_func(request, *args, **kwargs)
  File "C:\Users\heeeepin\Desktop\TiebaProject\venv\lib\site-packages\django\contrib\admin\options.py", line 1671, in changelist_view
    raise PermissionDenied
django.core.exceptions.PermissionDenied
2020-01-05 log.py[line:228] Not Found: /favicon.ico
2020-01-05 log.py[line:228] Internal Server Error: /admin/SignIn/user/add/
Traceback (most recent call last):
  File "C:\Users\heeeepin\Desktop\TiebaProject\venv\lib\site-packages\django\db\backends\utils.py", line 85, in _execute
    return self.cursor.execute(sql, params)
  File "C:\Users\heeeepin\Desktop\TiebaProject\venv\lib\site-packages\django\db\backends\mysql\base.py", line 71, in execute
    return self.cursor.execute(query, args)
  File "C:\Users\heeeepin\Desktop\TiebaProject\venv\lib\site-packages\pymysql\cursors.py", line 170, in execute
    result = self._query(query)
  File "C:\Users\heeeepin\Desktop\TiebaProject\venv\lib\site-packages\pymysql\cursors.py", line 328, in _query
    conn.query(q)
  File "C:\Users\heeeepin\Desktop\TiebaProject\venv\lib\site-packages\pymysql\connections.py", line 517, in query
    self._affected_rows = self._read_query_result(unbuffered=unbuffered)
  File "C:\Users\heeeepin\Desktop\TiebaProject\venv\lib\site-packages\pymysql\connections.py", line 732, in _read_query_result
    result.read()
  File "C:\Users\heeeepin\Desktop\TiebaProject\venv\lib\site-packages\pymysql\connections.py", line 1075, in read
    first_packet = self.connection._read_packet()
  File "C:\Users\heeeepin\Desktop\TiebaProject\venv\lib\site-packages\pymysql\connections.py", line 684, in _read_packet
    packet.check_error()
  File "C:\Users\heeeepin\Desktop\TiebaProject\venv\lib\site-packages\pymysql\protocol.py", line 220, in check_error
    err.raise_mysql_exception(self._data)
  File "C:\Users\heeeepin\Desktop\TiebaProject\venv\lib\site-packages\pymysql\err.py", line 109, in raise_mysql_exception
    raise errorclass(errno, errval)
pymysql.err.IntegrityError: (1062, "Duplicate entry '' for key 'username'")

The above exception was the direct cause of the following exception:

Traceback (most recent call last):
  File "C:\Users\heeeepin\Desktop\TiebaProject\venv\lib\site-packages\django\core\handlers\exception.py", line 34, in inner
    response = get_response(request)
  File "C:\Users\heeeepin\Desktop\TiebaProject\venv\lib\site-packages\django\core\handlers\base.py", line 126, in _get_response
    response = self.process_exception_by_middleware(e, request)
  File "C:\Users\heeeepin\Desktop\TiebaProject\venv\lib\site-packages\django\core\handlers\base.py", line 124, in _get_response
    response = wrapped_callback(request, *callback_args, **callback_kwargs)
  File "C:\Users\heeeepin\Desktop\TiebaProject\venv\lib\site-packages\django\contrib\admin\options.py", line 604, in wrapper
    return self.admin_site.admin_view(view)(*args, **kwargs)
  File "C:\Users\heeeepin\Desktop\TiebaProject\venv\lib\site-packages\django\utils\decorators.py", line 142, in _wrapped_view
    response = view_func(request, *args, **kwargs)
  File "C:\Users\heeeepin\Desktop\TiebaProject\venv\lib\site-packages\django\views\decorators\cache.py", line 44, in _wrapped_view_func
    response = view_func(request, *args, **kwargs)
  File "C:\Users\heeeepin\Desktop\TiebaProject\venv\lib\site-packages\django\contrib\admin\sites.py", line 223, in inner
    return view(request, *args, **kwargs)
  File "C:\Users\heeeepin\Desktop\TiebaProject\venv\lib\site-packages\django\contrib\admin\options.py", line 1636, in add_view
    return self.changeform_view(request, None, form_url, extra_context)
  File "C:\Users\heeeepin\Desktop\TiebaProject\venv\lib\site-packages\django\utils\decorators.py", line 45, in _wrapper
    return bound_method(*args, **kwargs)
  File "C:\Users\heeeepin\Desktop\TiebaProject\venv\lib\site-packages\django\utils\decorators.py", line 142, in _wrapped_view
    response = view_func(request, *args, **kwargs)
  File "C:\Users\heeeepin\Desktop\TiebaProject\venv\lib\site-packages\django\contrib\admin\options.py", line 1525, in changeform_view
    return self._changeform_view(request, object_id, form_url, extra_context)
  File "C:\Users\heeeepin\Desktop\TiebaProject\venv\lib\site-packages\django\contrib\admin\options.py", line 1564, in _changeform_view
    self.save_model(request, new_object, form, not add)
  File "C:\Users\heeeepin\Desktop\TiebaProject\SignIn\admin.py", line 57, in save_model
    result = super().save_model(request, obj, form, change)
  File "C:\Users\heeeepin\Desktop\TiebaProject\venv\lib\site-packages\django\contrib\admin\options.py", line 1091, in save_model
    obj.save()
  File "C:\Users\heeeepin\Desktop\TiebaProject\venv\lib\site-packages\django\db\models\base.py", line 718, in save
    force_update=force_update, update_fields=update_fields)
  File "C:\Users\heeeepin\Desktop\TiebaProject\venv\lib\site-packages\django\db\models\base.py", line 748, in save_base
    updated = self._save_table(raw, cls, force_insert, force_update, using, update_fields)
  File "C:\Users\heeeepin\Desktop\TiebaProject\venv\lib\site-packages\django\db\models\base.py", line 831, in _save_table
    result = self._do_insert(cls._base_manager, using, fields, update_pk, raw)
  File "C:\Users\heeeepin\Desktop\TiebaProject\venv\lib\site-packages\django\db\models\base.py", line 869, in _do_insert
    using=using, raw=raw)
  File "C:\Users\heeeepin\Desktop\TiebaProject\venv\lib\site-packages\django\db\models\manager.py", line 82, in manager_method
    return getattr(self.get_queryset(), name)(*args, **kwargs)
  File "C:\Users\heeeepin\Desktop\TiebaProject\venv\lib\site-packages\django\db\models\query.py", line 1136, in _insert
    return query.get_compiler(using=using).execute_sql(return_id)
  File "C:\Users\heeeepin\Desktop\TiebaProject\venv\lib\site-packages\django\db\models\sql\compiler.py", line 1289, in execute_sql
    cursor.execute(sql, params)
  File "C:\Users\heeeepin\Desktop\TiebaProject\venv\lib\site-packages\django\db\backends\utils.py", line 100, in execute
    return super().execute(sql, params)
  File "C:\Users\heeeepin\Desktop\TiebaProject\venv\lib\site-packages\django\db\backends\utils.py", line 68, in execute
    return self._execute_with_wrappers(sql, params, many=False, executor=self._execute)
  File "C:\Users\heeeepin\Desktop\TiebaProject\venv\lib\site-packages\django\db\backends\utils.py", line 77, in _execute_with_wrappers
    return executor(sql, params, many, context)
  File "C:\Users\heeeepin\Desktop\TiebaProject\venv\lib\site-packages\django\db\backends\utils.py", line 85, in _execute
    return self.cursor.execute(sql, params)
  File "C:\Users\heeeepin\Desktop\TiebaProject\venv\lib\site-packages\django\db\utils.py", line 89, in __exit__
    raise dj_exc_value.with_traceback(traceback) from exc_value
  File "C:\Users\heeeepin\Desktop\TiebaProject\venv\lib\site-packages\django\db\backends\utils.py", line 85, in _execute
    return self.cursor.execute(sql, params)
  File "C:\Users\heeeepin\Desktop\TiebaProject\venv\lib\site-packages\django\db\backends\mysql\base.py", line 71, in execute
    return self.cursor.execute(query, args)
  File "C:\Users\heeeepin\Desktop\TiebaProject\venv\lib\site-packages\pymysql\cursors.py", line 170, in execute
    result = self._query(query)
  File "C:\Users\heeeepin\Desktop\TiebaProject\venv\lib\site-packages\pymysql\cursors.py", line 328, in _query
    conn.query(q)
  File "C:\Users\heeeepin\Desktop\TiebaProject\venv\lib\site-packages\pymysql\connections.py", line 517, in query
    self._affected_rows = self._read_query_result(unbuffered=unbuffered)
  File "C:\Users\heeeepin\Desktop\TiebaProject\venv\lib\site-packages\pymysql\connections.py", line 732, in _read_query_result
    result.read()
  File "C:\Users\heeeepin\Desktop\TiebaProject\venv\lib\site-packages\pymysql\connections.py", line 1075, in read
    first_packet = self.connection._read_packet()
  File "C:\Users\heeeepin\Desktop\TiebaProject\venv\lib\site-packages\pymysql\connections.py", line 684, in _read_packet
    packet.check_error()
  File "C:\Users\heeeepin\Desktop\TiebaProject\venv\lib\site-packages\pymysql\protocol.py", line 220, in check_error
    err.raise_mysql_exception(self._data)
  File "C:\Users\heeeepin\Desktop\TiebaProject\venv\lib\site-packages\pymysql\err.py", line 109, in raise_mysql_exception
    raise errorclass(errno, errval)
django.db.utils.IntegrityError: (1062, "Duplicate entry '' for key 'username'")
2020-01-05 log.py[line:228] Internal Server Error: /admin/SignIn/user/add/
Traceback (most recent call last):
  File "C:\Users\heeeepin\Desktop\TiebaProject\venv\lib\site-packages\django\db\backends\utils.py", line 85, in _execute
    return self.cursor.execute(sql, params)
  File "C:\Users\heeeepin\Desktop\TiebaProject\venv\lib\site-packages\django\db\backends\mysql\base.py", line 71, in execute
    return self.cursor.execute(query, args)
  File "C:\Users\heeeepin\Desktop\TiebaProject\venv\lib\site-packages\pymysql\cursors.py", line 170, in execute
    result = self._query(query)
  File "C:\Users\heeeepin\Desktop\TiebaProject\venv\lib\site-packages\pymysql\cursors.py", line 328, in _query
    conn.query(q)
  File "C:\Users\heeeepin\Desktop\TiebaProject\venv\lib\site-packages\pymysql\connections.py", line 517, in query
    self._affected_rows = self._read_query_result(unbuffered=unbuffered)
  File "C:\Users\heeeepin\Desktop\TiebaProject\venv\lib\site-packages\pymysql\connections.py", line 732, in _read_query_result
    result.read()
  File "C:\Users\heeeepin\Desktop\TiebaProject\venv\lib\site-packages\pymysql\connections.py", line 1075, in read
    first_packet = self.connection._read_packet()
  File "C:\Users\heeeepin\Desktop\TiebaProject\venv\lib\site-packages\pymysql\connections.py", line 684, in _read_packet
    packet.check_error()
  File "C:\Users\heeeepin\Desktop\TiebaProject\venv\lib\site-packages\pymysql\protocol.py", line 220, in check_error
    err.raise_mysql_exception(self._data)
  File "C:\Users\heeeepin\Desktop\TiebaProject\venv\lib\site-packages\pymysql\err.py", line 109, in raise_mysql_exception
    raise errorclass(errno, errval)
pymysql.err.IntegrityError: (1062, "Duplicate entry '' for key 'username'")

The above exception was the direct cause of the following exception:

Traceback (most recent call last):
  File "C:\Users\heeeepin\Desktop\TiebaProject\venv\lib\site-packages\django\core\handlers\exception.py", line 34, in inner
    response = get_response(request)
  File "C:\Users\heeeepin\Desktop\TiebaProject\venv\lib\site-packages\django\core\handlers\base.py", line 126, in _get_response
    response = self.process_exception_by_middleware(e, request)
  File "C:\Users\heeeepin\Desktop\TiebaProject\venv\lib\site-packages\django\core\handlers\base.py", line 124, in _get_response
    response = wrapped_callback(request, *callback_args, **callback_kwargs)
  File "C:\Users\heeeepin\Desktop\TiebaProject\venv\lib\site-packages\django\contrib\admin\options.py", line 604, in wrapper
    return self.admin_site.admin_view(view)(*args, **kwargs)
  File "C:\Users\heeeepin\Desktop\TiebaProject\venv\lib\site-packages\django\utils\decorators.py", line 142, in _wrapped_view
    response = view_func(request, *args, **kwargs)
  File "C:\Users\heeeepin\Desktop\TiebaProject\venv\lib\site-packages\django\views\decorators\cache.py", line 44, in _wrapped_view_func
    response = view_func(request, *args, **kwargs)
  File "C:\Users\heeeepin\Desktop\TiebaProject\venv\lib\site-packages\django\contrib\admin\sites.py", line 223, in inner
    return view(request, *args, **kwargs)
  File "C:\Users\heeeepin\Desktop\TiebaProject\venv\lib\site-packages\django\contrib\admin\options.py", line 1636, in add_view
    return self.changeform_view(request, None, form_url, extra_context)
  File "C:\Users\heeeepin\Desktop\TiebaProject\venv\lib\site-packages\django\utils\decorators.py", line 45, in _wrapper
    return bound_method(*args, **kwargs)
  File "C:\Users\heeeepin\Desktop\TiebaProject\venv\lib\site-packages\django\utils\decorators.py", line 142, in _wrapped_view
    response = view_func(request, *args, **kwargs)
  File "C:\Users\heeeepin\Desktop\TiebaProject\venv\lib\site-packages\django\contrib\admin\options.py", line 1525, in changeform_view
    return self._changeform_view(request, object_id, form_url, extra_context)
  File "C:\Users\heeeepin\Desktop\TiebaProject\venv\lib\site-packages\django\contrib\admin\options.py", line 1564, in _changeform_view
    self.save_model(request, new_object, form, not add)
  File "C:\Users\heeeepin\Desktop\TiebaProject\SignIn\admin.py", line 57, in save_model
    result = super().save_model(request, obj, form, change)
  File "C:\Users\heeeepin\Desktop\TiebaProject\venv\lib\site-packages\django\contrib\admin\options.py", line 1091, in save_model
    obj.save()
  File "C:\Users\heeeepin\Desktop\TiebaProject\venv\lib\site-packages\django\db\models\base.py", line 718, in save
    force_update=force_update, update_fields=update_fields)
  File "C:\Users\heeeepin\Desktop\TiebaProject\venv\lib\site-packages\django\db\models\base.py", line 748, in save_base
    updated = self._save_table(raw, cls, force_insert, force_update, using, update_fields)
  File "C:\Users\heeeepin\Desktop\TiebaProject\venv\lib\site-packages\django\db\models\base.py", line 831, in _save_table
    result = self._do_insert(cls._base_manager, using, fields, update_pk, raw)
  File "C:\Users\heeeepin\Desktop\TiebaProject\venv\lib\site-packages\django\db\models\base.py", line 869, in _do_insert
    using=using, raw=raw)
  File "C:\Users\heeeepin\Desktop\TiebaProject\venv\lib\site-packages\django\db\models\manager.py", line 82, in manager_method
    return getattr(self.get_queryset(), name)(*args, **kwargs)
  File "C:\Users\heeeepin\Desktop\TiebaProject\venv\lib\site-packages\django\db\models\query.py", line 1136, in _insert
    return query.get_compiler(using=using).execute_sql(return_id)
  File "C:\Users\heeeepin\Desktop\TiebaProject\venv\lib\site-packages\django\db\models\sql\compiler.py", line 1289, in execute_sql
    cursor.execute(sql, params)
  File "C:\Users\heeeepin\Desktop\TiebaProject\venv\lib\site-packages\django\db\backends\utils.py", line 100, in execute
    return super().execute(sql, params)
  File "C:\Users\heeeepin\Desktop\TiebaProject\venv\lib\site-packages\django\db\backends\utils.py", line 68, in execute
    return self._execute_with_wrappers(sql, params, many=False, executor=self._execute)
  File "C:\Users\heeeepin\Desktop\TiebaProject\venv\lib\site-packages\django\db\backends\utils.py", line 77, in _execute_with_wrappers
    return executor(sql, params, many, context)
  File "C:\Users\heeeepin\Desktop\TiebaProject\venv\lib\site-packages\django\db\backends\utils.py", line 85, in _execute
    return self.cursor.execute(sql, params)
  File "C:\Users\heeeepin\Desktop\TiebaProject\venv\lib\site-packages\django\db\utils.py", line 89, in __exit__
    raise dj_exc_value.with_traceback(traceback) from exc_value
  File "C:\Users\heeeepin\Desktop\TiebaProject\venv\lib\site-packages\django\db\backends\utils.py", line 85, in _execute
    return self.cursor.execute(sql, params)
  File "C:\Users\heeeepin\Desktop\TiebaProject\venv\lib\site-packages\django\db\backends\mysql\base.py", line 71, in execute
    return self.cursor.execute(query, args)
  File "C:\Users\heeeepin\Desktop\TiebaProject\venv\lib\site-packages\pymysql\cursors.py", line 170, in execute
    result = self._query(query)
  File "C:\Users\heeeepin\Desktop\TiebaProject\venv\lib\site-packages\pymysql\cursors.py", line 328, in _query
    conn.query(q)
  File "C:\Users\heeeepin\Desktop\TiebaProject\venv\lib\site-packages\pymysql\connections.py", line 517, in query
    self._affected_rows = self._read_query_result(unbuffered=unbuffered)
  File "C:\Users\heeeepin\Desktop\TiebaProject\venv\lib\site-packages\pymysql\connections.py", line 732, in _read_query_result
    result.read()
  File "C:\Users\heeeepin\Desktop\TiebaProject\venv\lib\site-packages\pymysql\connections.py", line 1075, in read
    first_packet = self.connection._read_packet()
  File "C:\Users\heeeepin\Desktop\TiebaProject\venv\lib\site-packages\pymysql\connections.py", line 684, in _read_packet
    packet.check_error()
  File "C:\Users\heeeepin\Desktop\TiebaProject\venv\lib\site-packages\pymysql\protocol.py", line 220, in check_error
    err.raise_mysql_exception(self._data)
  File "C:\Users\heeeepin\Desktop\TiebaProject\venv\lib\site-packages\pymysql\err.py", line 109, in raise_mysql_exception
    raise errorclass(errno, errval)
django.db.utils.IntegrityError: (1062, "Duplicate entry '' for key 'username'")
2020-01-05 log.py[line:228] Internal Server Error: /admin/SignIn/user/add/
Traceback (most recent call last):
  File "C:\Users\heeeepin\Desktop\TiebaProject\venv\lib\site-packages\django\db\backends\utils.py", line 85, in _execute
    return self.cursor.execute(sql, params)
  File "C:\Users\heeeepin\Desktop\TiebaProject\venv\lib\site-packages\django\db\backends\mysql\base.py", line 71, in execute
    return self.cursor.execute(query, args)
  File "C:\Users\heeeepin\Desktop\TiebaProject\venv\lib\site-packages\pymysql\cursors.py", line 170, in execute
    result = self._query(query)
  File "C:\Users\heeeepin\Desktop\TiebaProject\venv\lib\site-packages\pymysql\cursors.py", line 328, in _query
    conn.query(q)
  File "C:\Users\heeeepin\Desktop\TiebaProject\venv\lib\site-packages\pymysql\connections.py", line 517, in query
    self._affected_rows = self._read_query_result(unbuffered=unbuffered)
  File "C:\Users\heeeepin\Desktop\TiebaProject\venv\lib\site-packages\pymysql\connections.py", line 732, in _read_query_result
    result.read()
  File "C:\Users\heeeepin\Desktop\TiebaProject\venv\lib\site-packages\pymysql\connections.py", line 1075, in read
    first_packet = self.connection._read_packet()
  File "C:\Users\heeeepin\Desktop\TiebaProject\venv\lib\site-packages\pymysql\connections.py", line 684, in _read_packet
    packet.check_error()
  File "C:\Users\heeeepin\Desktop\TiebaProject\venv\lib\site-packages\pymysql\protocol.py", line 220, in check_error
    err.raise_mysql_exception(self._data)
  File "C:\Users\heeeepin\Desktop\TiebaProject\venv\lib\site-packages\pymysql\err.py", line 109, in raise_mysql_exception
    raise errorclass(errno, errval)
pymysql.err.IntegrityError: (1062, "Duplicate entry '' for key 'username'")

The above exception was the direct cause of the following exception:

Traceback (most recent call last):
  File "C:\Users\heeeepin\Desktop\TiebaProject\venv\lib\site-packages\django\core\handlers\exception.py", line 34, in inner
    response = get_response(request)
  File "C:\Users\heeeepin\Desktop\TiebaProject\venv\lib\site-packages\django\core\handlers\base.py", line 126, in _get_response
    response = self.process_exception_by_middleware(e, request)
  File "C:\Users\heeeepin\Desktop\TiebaProject\venv\lib\site-packages\django\core\handlers\base.py", line 124, in _get_response
    response = wrapped_callback(request, *callback_args, **callback_kwargs)
  File "C:\Users\heeeepin\Desktop\TiebaProject\venv\lib\site-packages\django\contrib\admin\options.py", line 604, in wrapper
    return self.admin_site.admin_view(view)(*args, **kwargs)
  File "C:\Users\heeeepin\Desktop\TiebaProject\venv\lib\site-packages\django\utils\decorators.py", line 142, in _wrapped_view
    response = view_func(request, *args, **kwargs)
  File "C:\Users\heeeepin\Desktop\TiebaProject\venv\lib\site-packages\django\views\decorators\cache.py", line 44, in _wrapped_view_func
    response = view_func(request, *args, **kwargs)
  File "C:\Users\heeeepin\Desktop\TiebaProject\venv\lib\site-packages\django\contrib\admin\sites.py", line 223, in inner
    return view(request, *args, **kwargs)
  File "C:\Users\heeeepin\Desktop\TiebaProject\venv\lib\site-packages\django\contrib\admin\options.py", line 1636, in add_view
    return self.changeform_view(request, None, form_url, extra_context)
  File "C:\Users\heeeepin\Desktop\TiebaProject\venv\lib\site-packages\django\utils\decorators.py", line 45, in _wrapper
    return bound_method(*args, **kwargs)
  File "C:\Users\heeeepin\Desktop\TiebaProject\venv\lib\site-packages\django\utils\decorators.py", line 142, in _wrapped_view
    response = view_func(request, *args, **kwargs)
  File "C:\Users\heeeepin\Desktop\TiebaProject\venv\lib\site-packages\django\contrib\admin\options.py", line 1525, in changeform_view
    return self._changeform_view(request, object_id, form_url, extra_context)
  File "C:\Users\heeeepin\Desktop\TiebaProject\venv\lib\site-packages\django\contrib\admin\options.py", line 1564, in _changeform_view
    self.save_model(request, new_object, form, not add)
  File "C:\Users\heeeepin\Desktop\TiebaProject\SignIn\admin.py", line 57, in save_model
    result = super().save_model(request, obj, form, change)
  File "C:\Users\heeeepin\Desktop\TiebaProject\venv\lib\site-packages\django\contrib\admin\options.py", line 1091, in save_model
    obj.save()
  File "C:\Users\heeeepin\Desktop\TiebaProject\venv\lib\site-packages\django\db\models\base.py", line 718, in save
    force_update=force_update, update_fields=update_fields)
  File "C:\Users\heeeepin\Desktop\TiebaProject\venv\lib\site-packages\django\db\models\base.py", line 748, in save_base
    updated = self._save_table(raw, cls, force_insert, force_update, using, update_fields)
  File "C:\Users\heeeepin\Desktop\TiebaProject\venv\lib\site-packages\django\db\models\base.py", line 831, in _save_table
    result = self._do_insert(cls._base_manager, using, fields, update_pk, raw)
  File "C:\Users\heeeepin\Desktop\TiebaProject\venv\lib\site-packages\django\db\models\base.py", line 869, in _do_insert
    using=using, raw=raw)
  File "C:\Users\heeeepin\Desktop\TiebaProject\venv\lib\site-packages\django\db\models\manager.py", line 82, in manager_method
    return getattr(self.get_queryset(), name)(*args, **kwargs)
  File "C:\Users\heeeepin\Desktop\TiebaProject\venv\lib\site-packages\django\db\models\query.py", line 1136, in _insert
    return query.get_compiler(using=using).execute_sql(return_id)
  File "C:\Users\heeeepin\Desktop\TiebaProject\venv\lib\site-packages\django\db\models\sql\compiler.py", line 1289, in execute_sql
    cursor.execute(sql, params)
  File "C:\Users\heeeepin\Desktop\TiebaProject\venv\lib\site-packages\django\db\backends\utils.py", line 100, in execute
    return super().execute(sql, params)
  File "C:\Users\heeeepin\Desktop\TiebaProject\venv\lib\site-packages\django\db\backends\utils.py", line 68, in execute
    return self._execute_with_wrappers(sql, params, many=False, executor=self._execute)
  File "C:\Users\heeeepin\Desktop\TiebaProject\venv\lib\site-packages\django\db\backends\utils.py", line 77, in _execute_with_wrappers
    return executor(sql, params, many, context)
  File "C:\Users\heeeepin\Desktop\TiebaProject\venv\lib\site-packages\django\db\backends\utils.py", line 85, in _execute
    return self.cursor.execute(sql, params)
  File "C:\Users\heeeepin\Desktop\TiebaProject\venv\lib\site-packages\django\db\utils.py", line 89, in __exit__
    raise dj_exc_value.with_traceback(traceback) from exc_value
  File "C:\Users\heeeepin\Desktop\TiebaProject\venv\lib\site-packages\django\db\backends\utils.py", line 85, in _execute
    return self.cursor.execute(sql, params)
  File "C:\Users\heeeepin\Desktop\TiebaProject\venv\lib\site-packages\django\db\backends\mysql\base.py", line 71, in execute
    return self.cursor.execute(query, args)
  File "C:\Users\heeeepin\Desktop\TiebaProject\venv\lib\site-packages\pymysql\cursors.py", line 170, in execute
    result = self._query(query)
  File "C:\Users\heeeepin\Desktop\TiebaProject\venv\lib\site-packages\pymysql\cursors.py", line 328, in _query
    conn.query(q)
  File "C:\Users\heeeepin\Desktop\TiebaProject\venv\lib\site-packages\pymysql\connections.py", line 517, in query
    self._affected_rows = self._read_query_result(unbuffered=unbuffered)
  File "C:\Users\heeeepin\Desktop\TiebaProject\venv\lib\site-packages\pymysql\connections.py", line 732, in _read_query_result
    result.read()
  File "C:\Users\heeeepin\Desktop\TiebaProject\venv\lib\site-packages\pymysql\connections.py", line 1075, in read
    first_packet = self.connection._read_packet()
  File "C:\Users\heeeepin\Desktop\TiebaProject\venv\lib\site-packages\pymysql\connections.py", line 684, in _read_packet
    packet.check_error()
  File "C:\Users\heeeepin\Desktop\TiebaProject\venv\lib\site-packages\pymysql\protocol.py", line 220, in check_error
    err.raise_mysql_exception(self._data)
  File "C:\Users\heeeepin\Desktop\TiebaProject\venv\lib\site-packages\pymysql\err.py", line 109, in raise_mysql_exception
    raise errorclass(errno, errval)
django.db.utils.IntegrityError: (1062, "Duplicate entry '' for key 'username'")
2020-01-05 log.py[line:228] Forbidden (Permission denied): /admin/SignIn/user/1/change/
Traceback (most recent call last):
  File "C:\Users\heeeepin\Desktop\TiebaProject\venv\lib\site-packages\django\core\handlers\exception.py", line 34, in inner
    response = get_response(request)
  File "C:\Users\heeeepin\Desktop\TiebaProject\venv\lib\site-packages\django\core\handlers\base.py", line 126, in _get_response
    response = self.process_exception_by_middleware(e, request)
  File "C:\Users\heeeepin\Desktop\TiebaProject\venv\lib\site-packages\django\core\handlers\base.py", line 124, in _get_response
    response = wrapped_callback(request, *callback_args, **callback_kwargs)
  File "C:\Users\heeeepin\Desktop\TiebaProject\venv\lib\site-packages\django\contrib\admin\options.py", line 604, in wrapper
    return self.admin_site.admin_view(view)(*args, **kwargs)
  File "C:\Users\heeeepin\Desktop\TiebaProject\venv\lib\site-packages\django\utils\decorators.py", line 142, in _wrapped_view
    response = view_func(request, *args, **kwargs)
  File "C:\Users\heeeepin\Desktop\TiebaProject\venv\lib\site-packages\django\views\decorators\cache.py", line 44, in _wrapped_view_func
    response = view_func(request, *args, **kwargs)
  File "C:\Users\heeeepin\Desktop\TiebaProject\venv\lib\site-packages\django\contrib\admin\sites.py", line 223, in inner
    return view(request, *args, **kwargs)
  File "C:\Users\heeeepin\Desktop\TiebaProject\venv\lib\site-packages\django\contrib\admin\options.py", line 1639, in change_view
    return self.changeform_view(request, object_id, form_url, extra_context)
  File "C:\Users\heeeepin\Desktop\TiebaProject\venv\lib\site-packages\django\utils\decorators.py", line 45, in _wrapper
    return bound_method(*args, **kwargs)
  File "C:\Users\heeeepin\Desktop\TiebaProject\venv\lib\site-packages\django\utils\decorators.py", line 142, in _wrapped_view
    response = view_func(request, *args, **kwargs)
  File "C:\Users\heeeepin\Desktop\TiebaProject\venv\lib\site-packages\django\contrib\admin\options.py", line 1525, in changeform_view
    return self._changeform_view(request, object_id, form_url, extra_context)
  File "C:\Users\heeeepin\Desktop\TiebaProject\venv\lib\site-packages\django\contrib\admin\options.py", line 1549, in _changeform_view
    raise PermissionDenied
django.core.exceptions.PermissionDenied
2020-01-05 log.py[line:228] Forbidden (Permission denied): /admin/auth/user/
Traceback (most recent call last):
  File "C:\Users\heeeepin\Desktop\TiebaProject\venv\lib\site-packages\django\core\handlers\exception.py", line 34, in inner
    response = get_response(request)
  File "C:\Users\heeeepin\Desktop\TiebaProject\venv\lib\site-packages\django\core\handlers\base.py", line 126, in _get_response
    response = self.process_exception_by_middleware(e, request)
  File "C:\Users\heeeepin\Desktop\TiebaProject\venv\lib\site-packages\django\core\handlers\base.py", line 124, in _get_response
    response = wrapped_callback(request, *callback_args, **callback_kwargs)
  File "C:\Users\heeeepin\Desktop\TiebaProject\venv\lib\site-packages\django\contrib\admin\options.py", line 604, in wrapper
    return self.admin_site.admin_view(view)(*args, **kwargs)
  File "C:\Users\heeeepin\Desktop\TiebaProject\venv\lib\site-packages\django\utils\decorators.py", line 142, in _wrapped_view
    response = view_func(request, *args, **kwargs)
  File "C:\Users\heeeepin\Desktop\TiebaProject\venv\lib\site-packages\django\views\decorators\cache.py", line 44, in _wrapped_view_func
    response = view_func(request, *args, **kwargs)
  File "C:\Users\heeeepin\Desktop\TiebaProject\venv\lib\site-packages\django\contrib\admin\sites.py", line 223, in inner
    return view(request, *args, **kwargs)
  File "C:\Users\heeeepin\Desktop\TiebaProject\venv\lib\site-packages\django\utils\decorators.py", line 45, in _wrapper
    return bound_method(*args, **kwargs)
  File "C:\Users\heeeepin\Desktop\TiebaProject\venv\lib\site-packages\django\utils\decorators.py", line 142, in _wrapped_view
    response = view_func(request, *args, **kwargs)
  File "C:\Users\heeeepin\Desktop\TiebaProject\venv\lib\site-packages\django\contrib\admin\options.py", line 1671, in changelist_view
    raise PermissionDenied
django.core.exceptions.PermissionDenied
2020-01-05 log.py[line:228] Internal Server Error: /admin/SignIn/user/
Traceback (most recent call last):
  File "C:\Users\heeeepin\Desktop\TiebaProject\venv\lib\site-packages\django\core\handlers\exception.py", line 34, in inner
    response = get_response(request)
  File "C:\Users\heeeepin\Desktop\TiebaProject\venv\lib\site-packages\django\core\handlers\base.py", line 126, in _get_response
    response = self.process_exception_by_middleware(e, request)
  File "C:\Users\heeeepin\Desktop\TiebaProject\venv\lib\site-packages\django\core\handlers\base.py", line 124, in _get_response
    response = wrapped_callback(request, *callback_args, **callback_kwargs)
  File "C:\Users\heeeepin\Desktop\TiebaProject\venv\lib\site-packages\django\contrib\admin\options.py", line 604, in wrapper
    return self.admin_site.admin_view(view)(*args, **kwargs)
  File "C:\Users\heeeepin\Desktop\TiebaProject\venv\lib\site-packages\django\utils\decorators.py", line 142, in _wrapped_view
    response = view_func(request, *args, **kwargs)
  File "C:\Users\heeeepin\Desktop\TiebaProject\venv\lib\site-packages\django\views\decorators\cache.py", line 44, in _wrapped_view_func
    response = view_func(request, *args, **kwargs)
  File "C:\Users\heeeepin\Desktop\TiebaProject\venv\lib\site-packages\django\contrib\admin\sites.py", line 223, in inner
    return view(request, *args, **kwargs)
  File "C:\Users\heeeepin\Desktop\TiebaProject\venv\lib\site-packages\django\utils\decorators.py", line 45, in _wrapper
    return bound_method(*args, **kwargs)
  File "C:\Users\heeeepin\Desktop\TiebaProject\venv\lib\site-packages\django\utils\decorators.py", line 142, in _wrapped_view
    response = view_func(request, *args, **kwargs)
  File "C:\Users\heeeepin\Desktop\TiebaProject\venv\lib\site-packages\django\contrib\admin\options.py", line 1674, in changelist_view
    cl = self.get_changelist_instance(request)
  File "C:\Users\heeeepin\Desktop\TiebaProject\venv\lib\site-packages\django\contrib\admin\options.py", line 742, in get_changelist_instance
    sortable_by,
  File "C:\Users\heeeepin\Desktop\TiebaProject\venv\lib\site-packages\django\contrib\admin\views\main.py", line 45, in __init__
    self.root_queryset = model_admin.get_queryset(request)
  File "C:\Users\heeeepin\Desktop\TiebaProject\SignIn\admin.py", line 10, in get_queryset
    return qs.filter(user=request.user)
  File "C:\Users\heeeepin\Desktop\TiebaProject\venv\lib\site-packages\django\db\models\query.py", line 844, in filter
    return self._filter_or_exclude(False, *args, **kwargs)
  File "C:\Users\heeeepin\Desktop\TiebaProject\venv\lib\site-packages\django\db\models\query.py", line 862, in _filter_or_exclude
    clone.query.add_q(Q(*args, **kwargs))
  File "C:\Users\heeeepin\Desktop\TiebaProject\venv\lib\site-packages\django\db\models\sql\query.py", line 1263, in add_q
    clause, _ = self._add_q(q_object, self.used_aliases)
  File "C:\Users\heeeepin\Desktop\TiebaProject\venv\lib\site-packages\django\db\models\sql\query.py", line 1287, in _add_q
    split_subq=split_subq,
  File "C:\Users\heeeepin\Desktop\TiebaProject\venv\lib\site-packages\django\db\models\sql\query.py", line 1164, in build_filter
    lookups, parts, reffed_expression = self.solve_lookup_type(arg)
  File "C:\Users\heeeepin\Desktop\TiebaProject\venv\lib\site-packages\django\db\models\sql\query.py", line 1028, in solve_lookup_type
    _, field, _, lookup_parts = self.names_to_path(lookup_splitted, self.get_meta())
  File "C:\Users\heeeepin\Desktop\TiebaProject\venv\lib\site-packages\django\db\models\sql\query.py", line 1389, in names_to_path
    "Choices are: %s" % (name, ", ".join(available)))
django.core.exceptions.FieldError: Cannot resolve keyword 'user' into field. Choices are: bduss, created_time, flag, id, sign, signlog, token, username
2020-01-06 log.py[line:228] Not Found: /favicon.ico
2020-01-06 log.py[line:228] Internal Server Error: /admin/SignIn/sign/
Traceback (most recent call last):
  File "C:\Users\heeeepin\Desktop\TiebaProject\venv\lib\site-packages\django\core\handlers\exception.py", line 34, in inner
    response = get_response(request)
  File "C:\Users\heeeepin\Desktop\TiebaProject\venv\lib\site-packages\django\core\handlers\base.py", line 126, in _get_response
    response = self.process_exception_by_middleware(e, request)
  File "C:\Users\heeeepin\Desktop\TiebaProject\venv\lib\site-packages\django\core\handlers\base.py", line 124, in _get_response
    response = wrapped_callback(request, *callback_args, **callback_kwargs)
  File "C:\Users\heeeepin\Desktop\TiebaProject\venv\lib\site-packages\django\contrib\admin\options.py", line 604, in wrapper
    return self.admin_site.admin_view(view)(*args, **kwargs)
  File "C:\Users\heeeepin\Desktop\TiebaProject\venv\lib\site-packages\django\utils\decorators.py", line 142, in _wrapped_view
    response = view_func(request, *args, **kwargs)
  File "C:\Users\heeeepin\Desktop\TiebaProject\venv\lib\site-packages\django\views\decorators\cache.py", line 44, in _wrapped_view_func
    response = view_func(request, *args, **kwargs)
  File "C:\Users\heeeepin\Desktop\TiebaProject\venv\lib\site-packages\django\contrib\admin\sites.py", line 223, in inner
    return view(request, *args, **kwargs)
  File "C:\Users\heeeepin\Desktop\TiebaProject\venv\lib\site-packages\django\utils\decorators.py", line 45, in _wrapper
    return bound_method(*args, **kwargs)
  File "C:\Users\heeeepin\Desktop\TiebaProject\venv\lib\site-packages\django\utils\decorators.py", line 142, in _wrapped_view
    response = view_func(request, *args, **kwargs)
  File "C:\Users\heeeepin\Desktop\TiebaProject\venv\lib\site-packages\django\contrib\admin\options.py", line 1674, in changelist_view
    cl = self.get_changelist_instance(request)
  File "C:\Users\heeeepin\Desktop\TiebaProject\venv\lib\site-packages\django\contrib\admin\options.py", line 742, in get_changelist_instance
    sortable_by,
  File "C:\Users\heeeepin\Desktop\TiebaProject\venv\lib\site-packages\django\contrib\admin\views\main.py", line 45, in __init__
    self.root_queryset = model_admin.get_queryset(request)
  File "C:\Users\heeeepin\Desktop\TiebaProject\SignIn\admin.py", line 11, in get_queryset
    return qs.filter(user==u)
NameError: name 'user' is not defined
2020-01-06 log.py[line:228] Internal Server Error: /admin/SignIn/signlog/
Traceback (most recent call last):
  File "C:\Users\heeeepin\Desktop\TiebaProject\venv\lib\site-packages\django\core\handlers\exception.py", line 34, in inner
    response = get_response(request)
  File "C:\Users\heeeepin\Desktop\TiebaProject\venv\lib\site-packages\django\core\handlers\base.py", line 126, in _get_response
    response = self.process_exception_by_middleware(e, request)
  File "C:\Users\heeeepin\Desktop\TiebaProject\venv\lib\site-packages\django\core\handlers\base.py", line 124, in _get_response
    response = wrapped_callback(request, *callback_args, **callback_kwargs)
  File "C:\Users\heeeepin\Desktop\TiebaProject\venv\lib\site-packages\django\contrib\admin\options.py", line 604, in wrapper
    return self.admin_site.admin_view(view)(*args, **kwargs)
  File "C:\Users\heeeepin\Desktop\TiebaProject\venv\lib\site-packages\django\utils\decorators.py", line 142, in _wrapped_view
    response = view_func(request, *args, **kwargs)
  File "C:\Users\heeeepin\Desktop\TiebaProject\venv\lib\site-packages\django\views\decorators\cache.py", line 44, in _wrapped_view_func
    response = view_func(request, *args, **kwargs)
  File "C:\Users\heeeepin\Desktop\TiebaProject\venv\lib\site-packages\django\contrib\admin\sites.py", line 223, in inner
    return view(request, *args, **kwargs)
  File "C:\Users\heeeepin\Desktop\TiebaProject\venv\lib\site-packages\django\utils\decorators.py", line 45, in _wrapper
    return bound_method(*args, **kwargs)
  File "C:\Users\heeeepin\Desktop\TiebaProject\venv\lib\site-packages\django\utils\decorators.py", line 142, in _wrapped_view
    response = view_func(request, *args, **kwargs)
  File "C:\Users\heeeepin\Desktop\TiebaProject\venv\lib\site-packages\django\contrib\admin\options.py", line 1674, in changelist_view
    cl = self.get_changelist_instance(request)
  File "C:\Users\heeeepin\Desktop\TiebaProject\venv\lib\site-packages\django\contrib\admin\options.py", line 742, in get_changelist_instance
    sortable_by,
  File "C:\Users\heeeepin\Desktop\TiebaProject\venv\lib\site-packages\django\contrib\admin\views\main.py", line 45, in __init__
    self.root_queryset = model_admin.get_queryset(request)
  File "C:\Users\heeeepin\Desktop\TiebaProject\SignIn\admin.py", line 29, in get_queryset
    return qs.filter(user=request.user)
  File "C:\Users\heeeepin\Desktop\TiebaProject\venv\lib\site-packages\django\db\models\query.py", line 844, in filter
    return self._filter_or_exclude(False, *args, **kwargs)
  File "C:\Users\heeeepin\Desktop\TiebaProject\venv\lib\site-packages\django\db\models\query.py", line 862, in _filter_or_exclude
    clone.query.add_q(Q(*args, **kwargs))
  File "C:\Users\heeeepin\Desktop\TiebaProject\venv\lib\site-packages\django\db\models\sql\query.py", line 1263, in add_q
    clause, _ = self._add_q(q_object, self.used_aliases)
  File "C:\Users\heeeepin\Desktop\TiebaProject\venv\lib\site-packages\django\db\models\sql\query.py", line 1287, in _add_q
    split_subq=split_subq,
  File "C:\Users\heeeepin\Desktop\TiebaProject\venv\lib\site-packages\django\db\models\sql\query.py", line 1198, in build_filter
    self.check_related_objects(join_info.final_field, value, join_info.opts)
  File "C:\Users\heeeepin\Desktop\TiebaProject\venv\lib\site-packages\django\db\models\sql\query.py", line 1063, in check_related_objects
    self.check_query_object_type(value, opts, field)
  File "C:\Users\heeeepin\Desktop\TiebaProject\venv\lib\site-packages\django\db\models\sql\query.py", line 1046, in check_query_object_type
    (value, opts.object_name))
ValueError: Cannot query "aaa": Must be "User" instance.
2020-01-06 log.py[line:228] Internal Server Error: /admin/SignIn/sign/
Traceback (most recent call last):
  File "C:\Users\heeeepin\Desktop\TiebaProject\venv\lib\site-packages\django\core\handlers\exception.py", line 34, in inner
    response = get_response(request)
  File "C:\Users\heeeepin\Desktop\TiebaProject\venv\lib\site-packages\django\core\handlers\base.py", line 126, in _get_response
    response = self.process_exception_by_middleware(e, request)
  File "C:\Users\heeeepin\Desktop\TiebaProject\venv\lib\site-packages\django\core\handlers\base.py", line 124, in _get_response
    response = wrapped_callback(request, *callback_args, **callback_kwargs)
  File "C:\Users\heeeepin\Desktop\TiebaProject\venv\lib\site-packages\django\contrib\admin\options.py", line 604, in wrapper
    return self.admin_site.admin_view(view)(*args, **kwargs)
  File "C:\Users\heeeepin\Desktop\TiebaProject\venv\lib\site-packages\django\utils\decorators.py", line 142, in _wrapped_view
    response = view_func(request, *args, **kwargs)
  File "C:\Users\heeeepin\Desktop\TiebaProject\venv\lib\site-packages\django\views\decorators\cache.py", line 44, in _wrapped_view_func
    response = view_func(request, *args, **kwargs)
  File "C:\Users\heeeepin\Desktop\TiebaProject\venv\lib\site-packages\django\contrib\admin\sites.py", line 223, in inner
    return view(request, *args, **kwargs)
  File "C:\Users\heeeepin\Desktop\TiebaProject\venv\lib\site-packages\django\utils\decorators.py", line 45, in _wrapper
    return bound_method(*args, **kwargs)
  File "C:\Users\heeeepin\Desktop\TiebaProject\venv\lib\site-packages\django\utils\decorators.py", line 142, in _wrapped_view
    response = view_func(request, *args, **kwargs)
  File "C:\Users\heeeepin\Desktop\TiebaProject\venv\lib\site-packages\django\contrib\admin\options.py", line 1674, in changelist_view
    cl = self.get_changelist_instance(request)
  File "C:\Users\heeeepin\Desktop\TiebaProject\venv\lib\site-packages\django\contrib\admin\options.py", line 742, in get_changelist_instance
    sortable_by,
  File "C:\Users\heeeepin\Desktop\TiebaProject\venv\lib\site-packages\django\contrib\admin\views\main.py", line 45, in __init__
    self.root_queryset = model_admin.get_queryset(request)
  File "C:\Users\heeeepin\Desktop\TiebaProject\SignIn\admin.py", line 11, in get_queryset
    return qs.filter('user'==u)
  File "C:\Users\heeeepin\Desktop\TiebaProject\venv\lib\site-packages\django\db\models\query.py", line 844, in filter
    return self._filter_or_exclude(False, *args, **kwargs)
  File "C:\Users\heeeepin\Desktop\TiebaProject\venv\lib\site-packages\django\db\models\query.py", line 862, in _filter_or_exclude
    clone.query.add_q(Q(*args, **kwargs))
  File "C:\Users\heeeepin\Desktop\TiebaProject\venv\lib\site-packages\django\db\models\sql\query.py", line 1263, in add_q
    clause, _ = self._add_q(q_object, self.used_aliases)
  File "C:\Users\heeeepin\Desktop\TiebaProject\venv\lib\site-packages\django\db\models\sql\query.py", line 1287, in _add_q
    split_subq=split_subq,
  File "C:\Users\heeeepin\Desktop\TiebaProject\venv\lib\site-packages\django\db\models\sql\query.py", line 1161, in build_filter
    arg, value = filter_expr
TypeError: 'bool' object is not iterable
2020-01-06 log.py[line:228] Internal Server Error: /admin/SignIn/signlog/
Traceback (most recent call last):
  File "C:\Users\heeeepin\Desktop\TiebaProject\venv\lib\site-packages\django\core\handlers\exception.py", line 34, in inner
    response = get_response(request)
  File "C:\Users\heeeepin\Desktop\TiebaProject\venv\lib\site-packages\django\core\handlers\base.py", line 126, in _get_response
    response = self.process_exception_by_middleware(e, request)
  File "C:\Users\heeeepin\Desktop\TiebaProject\venv\lib\site-packages\django\core\handlers\base.py", line 124, in _get_response
    response = wrapped_callback(request, *callback_args, **callback_kwargs)
  File "C:\Users\heeeepin\Desktop\TiebaProject\venv\lib\site-packages\django\contrib\admin\options.py", line 604, in wrapper
    return self.admin_site.admin_view(view)(*args, **kwargs)
  File "C:\Users\heeeepin\Desktop\TiebaProject\venv\lib\site-packages\django\utils\decorators.py", line 142, in _wrapped_view
    response = view_func(request, *args, **kwargs)
  File "C:\Users\heeeepin\Desktop\TiebaProject\venv\lib\site-packages\django\views\decorators\cache.py", line 44, in _wrapped_view_func
    response = view_func(request, *args, **kwargs)
  File "C:\Users\heeeepin\Desktop\TiebaProject\venv\lib\site-packages\django\contrib\admin\sites.py", line 223, in inner
    return view(request, *args, **kwargs)
  File "C:\Users\heeeepin\Desktop\TiebaProject\venv\lib\site-packages\django\utils\decorators.py", line 45, in _wrapper
    return bound_method(*args, **kwargs)
  File "C:\Users\heeeepin\Desktop\TiebaProject\venv\lib\site-packages\django\utils\decorators.py", line 142, in _wrapped_view
    response = view_func(request, *args, **kwargs)
  File "C:\Users\heeeepin\Desktop\TiebaProject\venv\lib\site-packages\django\contrib\admin\options.py", line 1674, in changelist_view
    cl = self.get_changelist_instance(request)
  File "C:\Users\heeeepin\Desktop\TiebaProject\venv\lib\site-packages\django\contrib\admin\options.py", line 742, in get_changelist_instance
    sortable_by,
  File "C:\Users\heeeepin\Desktop\TiebaProject\venv\lib\site-packages\django\contrib\admin\views\main.py", line 45, in __init__
    self.root_queryset = model_admin.get_queryset(request)
  File "C:\Users\heeeepin\Desktop\TiebaProject\SignIn\admin.py", line 29, in get_queryset
    return qs.filter(user=request.user)
  File "C:\Users\heeeepin\Desktop\TiebaProject\venv\lib\site-packages\django\db\models\query.py", line 844, in filter
    return self._filter_or_exclude(False, *args, **kwargs)
  File "C:\Users\heeeepin\Desktop\TiebaProject\venv\lib\site-packages\django\db\models\query.py", line 862, in _filter_or_exclude
    clone.query.add_q(Q(*args, **kwargs))
  File "C:\Users\heeeepin\Desktop\TiebaProject\venv\lib\site-packages\django\db\models\sql\query.py", line 1263, in add_q
    clause, _ = self._add_q(q_object, self.used_aliases)
  File "C:\Users\heeeepin\Desktop\TiebaProject\venv\lib\site-packages\django\db\models\sql\query.py", line 1287, in _add_q
    split_subq=split_subq,
  File "C:\Users\heeeepin\Desktop\TiebaProject\venv\lib\site-packages\django\db\models\sql\query.py", line 1198, in build_filter
    self.check_related_objects(join_info.final_field, value, join_info.opts)
  File "C:\Users\heeeepin\Desktop\TiebaProject\venv\lib\site-packages\django\db\models\sql\query.py", line 1063, in check_related_objects
    self.check_query_object_type(value, opts, field)
  File "C:\Users\heeeepin\Desktop\TiebaProject\venv\lib\site-packages\django\db\models\sql\query.py", line 1046, in check_query_object_type
    (value, opts.object_name))
ValueError: Cannot query "aaa": Must be "User" instance.
2020-01-06 log.py[line:228] Internal Server Error: /admin/SignIn/sign/
Traceback (most recent call last):
  File "C:\Users\heeeepin\Desktop\TiebaProject\venv\lib\site-packages\django\core\handlers\exception.py", line 34, in inner
    response = get_response(request)
  File "C:\Users\heeeepin\Desktop\TiebaProject\venv\lib\site-packages\django\core\handlers\base.py", line 126, in _get_response
    response = self.process_exception_by_middleware(e, request)
  File "C:\Users\heeeepin\Desktop\TiebaProject\venv\lib\site-packages\django\core\handlers\base.py", line 124, in _get_response
    response = wrapped_callback(request, *callback_args, **callback_kwargs)
  File "C:\Users\heeeepin\Desktop\TiebaProject\venv\lib\site-packages\django\contrib\admin\options.py", line 604, in wrapper
    return self.admin_site.admin_view(view)(*args, **kwargs)
  File "C:\Users\heeeepin\Desktop\TiebaProject\venv\lib\site-packages\django\utils\decorators.py", line 142, in _wrapped_view
    response = view_func(request, *args, **kwargs)
  File "C:\Users\heeeepin\Desktop\TiebaProject\venv\lib\site-packages\django\views\decorators\cache.py", line 44, in _wrapped_view_func
    response = view_func(request, *args, **kwargs)
  File "C:\Users\heeeepin\Desktop\TiebaProject\venv\lib\site-packages\django\contrib\admin\sites.py", line 223, in inner
    return view(request, *args, **kwargs)
  File "C:\Users\heeeepin\Desktop\TiebaProject\venv\lib\site-packages\django\utils\decorators.py", line 45, in _wrapper
    return bound_method(*args, **kwargs)
  File "C:\Users\heeeepin\Desktop\TiebaProject\venv\lib\site-packages\django\utils\decorators.py", line 142, in _wrapped_view
    response = view_func(request, *args, **kwargs)
  File "C:\Users\heeeepin\Desktop\TiebaProject\venv\lib\site-packages\django\contrib\admin\options.py", line 1674, in changelist_view
    cl = self.get_changelist_instance(request)
  File "C:\Users\heeeepin\Desktop\TiebaProject\venv\lib\site-packages\django\contrib\admin\options.py", line 742, in get_changelist_instance
    sortable_by,
  File "C:\Users\heeeepin\Desktop\TiebaProject\venv\lib\site-packages\django\contrib\admin\views\main.py", line 45, in __init__
    self.root_queryset = model_admin.get_queryset(request)
  File "C:\Users\heeeepin\Desktop\TiebaProject\SignIn\admin.py", line 19, in get_queryset
    return qs.filter('user' == u)
  File "C:\Users\heeeepin\Desktop\TiebaProject\venv\lib\site-packages\django\db\models\query.py", line 844, in filter
    return self._filter_or_exclude(False, *args, **kwargs)
  File "C:\Users\heeeepin\Desktop\TiebaProject\venv\lib\site-packages\django\db\models\query.py", line 862, in _filter_or_exclude
    clone.query.add_q(Q(*args, **kwargs))
  File "C:\Users\heeeepin\Desktop\TiebaProject\venv\lib\site-packages\django\db\models\sql\query.py", line 1263, in add_q
    clause, _ = self._add_q(q_object, self.used_aliases)
  File "C:\Users\heeeepin\Desktop\TiebaProject\venv\lib\site-packages\django\db\models\sql\query.py", line 1287, in _add_q
    split_subq=split_subq,
  File "C:\Users\heeeepin\Desktop\TiebaProject\venv\lib\site-packages\django\db\models\sql\query.py", line 1161, in build_filter
    arg, value = filter_expr
TypeError: 'bool' object is not iterable
2020-01-06 log.py[line:228] Internal Server Error: /admin/SignIn/sign/
Traceback (most recent call last):
  File "C:\Users\heeeepin\Desktop\TiebaProject\venv\lib\site-packages\django\core\handlers\exception.py", line 34, in inner
    response = get_response(request)
  File "C:\Users\heeeepin\Desktop\TiebaProject\venv\lib\site-packages\django\core\handlers\base.py", line 126, in _get_response
    response = self.process_exception_by_middleware(e, request)
  File "C:\Users\heeeepin\Desktop\TiebaProject\venv\lib\site-packages\django\core\handlers\base.py", line 124, in _get_response
    response = wrapped_callback(request, *callback_args, **callback_kwargs)
  File "C:\Users\heeeepin\Desktop\TiebaProject\venv\lib\site-packages\django\contrib\admin\options.py", line 604, in wrapper
    return self.admin_site.admin_view(view)(*args, **kwargs)
  File "C:\Users\heeeepin\Desktop\TiebaProject\venv\lib\site-packages\django\utils\decorators.py", line 142, in _wrapped_view
    response = view_func(request, *args, **kwargs)
  File "C:\Users\heeeepin\Desktop\TiebaProject\venv\lib\site-packages\django\views\decorators\cache.py", line 44, in _wrapped_view_func
    response = view_func(request, *args, **kwargs)
  File "C:\Users\heeeepin\Desktop\TiebaProject\venv\lib\site-packages\django\contrib\admin\sites.py", line 223, in inner
    return view(request, *args, **kwargs)
  File "C:\Users\heeeepin\Desktop\TiebaProject\venv\lib\site-packages\django\utils\decorators.py", line 45, in _wrapper
    return bound_method(*args, **kwargs)
  File "C:\Users\heeeepin\Desktop\TiebaProject\venv\lib\site-packages\django\utils\decorators.py", line 142, in _wrapped_view
    response = view_func(request, *args, **kwargs)
  File "C:\Users\heeeepin\Desktop\TiebaProject\venv\lib\site-packages\django\contrib\admin\options.py", line 1674, in changelist_view
    cl = self.get_changelist_instance(request)
  File "C:\Users\heeeepin\Desktop\TiebaProject\venv\lib\site-packages\django\contrib\admin\options.py", line 742, in get_changelist_instance
    sortable_by,
  File "C:\Users\heeeepin\Desktop\TiebaProject\venv\lib\site-packages\django\contrib\admin\views\main.py", line 45, in __init__
    self.root_queryset = model_admin.get_queryset(request)
  File "C:\Users\heeeepin\Desktop\TiebaProject\SignIn\admin.py", line 19, in get_queryset
    return qs.filter('user' == u)
  File "C:\Users\heeeepin\Desktop\TiebaProject\venv\lib\site-packages\django\db\models\query.py", line 844, in filter
    return self._filter_or_exclude(False, *args, **kwargs)
  File "C:\Users\heeeepin\Desktop\TiebaProject\venv\lib\site-packages\django\db\models\query.py", line 862, in _filter_or_exclude
    clone.query.add_q(Q(*args, **kwargs))
  File "C:\Users\heeeepin\Desktop\TiebaProject\venv\lib\site-packages\django\db\models\sql\query.py", line 1263, in add_q
    clause, _ = self._add_q(q_object, self.used_aliases)
  File "C:\Users\heeeepin\Desktop\TiebaProject\venv\lib\site-packages\django\db\models\sql\query.py", line 1287, in _add_q
    split_subq=split_subq,
  File "C:\Users\heeeepin\Desktop\TiebaProject\venv\lib\site-packages\django\db\models\sql\query.py", line 1161, in build_filter
    arg, value = filter_expr
TypeError: 'bool' object is not iterable
