2018-08-24 base.py[line:93] Not Found: /favicon.ico
2018-08-27 base.py[line:93] Not Found: /favicon.ico
2018-08-27 exception.py[line:118] Internal Server Error: /bduss/
Traceback (most recent call last):
  File "C:\Users\x86\AppData\Local\Programs\Python\Python36\lib\site-packages\urllib3\connectionpool.py", line 600, in urlopen
    chunked=chunked)
  File "C:\Users\x86\AppData\Local\Programs\Python\Python36\lib\site-packages\urllib3\connectionpool.py", line 343, in _make_request
    self._validate_conn(conn)
  File "C:\Users\x86\AppData\Local\Programs\Python\Python36\lib\site-packages\urllib3\connectionpool.py", line 849, in _validate_conn
    conn.connect()
  File "C:\Users\x86\AppData\Local\Programs\Python\Python36\lib\site-packages\urllib3\connection.py", line 356, in connect
    ssl_context=context)
  File "C:\Users\x86\AppData\Local\Programs\Python\Python36\lib\site-packages\urllib3\util\ssl_.py", line 359, in ssl_wrap_socket
    return context.wrap_socket(sock, server_hostname=server_hostname)
  File "C:\Users\x86\AppData\Local\Programs\Python\Python36\lib\ssl.py", line 407, in wrap_socket
    _context=self, _session=session)
  File "C:\Users\x86\AppData\Local\Programs\Python\Python36\lib\ssl.py", line 814, in __init__
    self.do_handshake()
  File "C:\Users\x86\AppData\Local\Programs\Python\Python36\lib\ssl.py", line 1068, in do_handshake
    self._sslobj.do_handshake()
  File "C:\Users\x86\AppData\Local\Programs\Python\Python36\lib\ssl.py", line 689, in do_handshake
    self._sslobj.do_handshake()
TimeoutError: [WinError 10060] 由于连接方在一段时间后没有正确答复或连接的主机没有反应，连接尝试失败。

During handling of the above exception, another exception occurred:

Traceback (most recent call last):
  File "C:\Users\x86\AppData\Local\Programs\Python\Python36\lib\site-packages\requests\adapters.py", line 445, in send
    timeout=timeout
  File "C:\Users\x86\AppData\Local\Programs\Python\Python36\lib\site-packages\urllib3\connectionpool.py", line 638, in urlopen
    _stacktrace=sys.exc_info()[2])
  File "C:\Users\x86\AppData\Local\Programs\Python\Python36\lib\site-packages\urllib3\util\retry.py", line 367, in increment
    raise six.reraise(type(error), error, _stacktrace)
  File "C:\Users\x86\AppData\Local\Programs\Python\Python36\lib\site-packages\urllib3\packages\six.py", line 685, in reraise
    raise value.with_traceback(tb)
  File "C:\Users\x86\AppData\Local\Programs\Python\Python36\lib\site-packages\urllib3\connectionpool.py", line 600, in urlopen
    chunked=chunked)
  File "C:\Users\x86\AppData\Local\Programs\Python\Python36\lib\site-packages\urllib3\connectionpool.py", line 343, in _make_request
    self._validate_conn(conn)
  File "C:\Users\x86\AppData\Local\Programs\Python\Python36\lib\site-packages\urllib3\connectionpool.py", line 849, in _validate_conn
    conn.connect()
  File "C:\Users\x86\AppData\Local\Programs\Python\Python36\lib\site-packages\urllib3\connection.py", line 356, in connect
    ssl_context=context)
  File "C:\Users\x86\AppData\Local\Programs\Python\Python36\lib\site-packages\urllib3\util\ssl_.py", line 359, in ssl_wrap_socket
    return context.wrap_socket(sock, server_hostname=server_hostname)
  File "C:\Users\x86\AppData\Local\Programs\Python\Python36\lib\ssl.py", line 407, in wrap_socket
    _context=self, _session=session)
  File "C:\Users\x86\AppData\Local\Programs\Python\Python36\lib\ssl.py", line 814, in __init__
    self.do_handshake()
  File "C:\Users\x86\AppData\Local\Programs\Python\Python36\lib\ssl.py", line 1068, in do_handshake
    self._sslobj.do_handshake()
  File "C:\Users\x86\AppData\Local\Programs\Python\Python36\lib\ssl.py", line 689, in do_handshake
    self._sslobj.do_handshake()
urllib3.exceptions.ProtocolError: ('Connection aborted.', TimeoutError(10060, '由于连接方在一段时间后没有正确答复或连接的主机没有反应，连接尝试失败。', None, 10060, None))

During handling of the above exception, another exception occurred:

Traceback (most recent call last):
  File "C:\Users\x86\AppData\Local\Programs\Python\Python36\lib\site-packages\django\core\handlers\exception.py", line 35, in inner
    response = get_response(request)
  File "C:\Users\x86\AppData\Local\Programs\Python\Python36\lib\site-packages\django\core\handlers\base.py", line 128, in _get_response
    response = self.process_exception_by_middleware(e, request)
  File "C:\Users\x86\AppData\Local\Programs\Python\Python36\lib\site-packages\django\core\handlers\base.py", line 126, in _get_response
    response = wrapped_callback(request, *callback_args, **callback_kwargs)
  File "C:\Users\x86\Desktop\开发\TiebaProject\YunHui\views.py", line 174, in bduss
    res2 = s.get(url=url2, headers=headers2).text[1:-2]
  File "C:\Users\x86\AppData\Local\Programs\Python\Python36\lib\site-packages\requests\sessions.py", line 525, in get
    return self.request('GET', url, **kwargs)
  File "C:\Users\x86\AppData\Local\Programs\Python\Python36\lib\site-packages\requests\sessions.py", line 512, in request
    resp = self.send(prep, **send_kwargs)
  File "C:\Users\x86\AppData\Local\Programs\Python\Python36\lib\site-packages\requests\sessions.py", line 622, in send
    r = adapter.send(request, **kwargs)
  File "C:\Users\x86\AppData\Local\Programs\Python\Python36\lib\site-packages\requests\adapters.py", line 495, in send
    raise ConnectionError(err, request=request)
requests.exceptions.ConnectionError: ('Connection aborted.', TimeoutError(10060, '由于连接方在一段时间后没有正确答复或连接的主机没有反应，连接尝试失败。', None, 10060, None))
2018-08-27 base.py[line:93] Not Found: /static/admin/css/base.css
2018-08-27 base.py[line:93] Not Found: /static/admin/css/login.css
2018-08-27 base.py[line:93] Not Found: /static/admin/css/responsive.css
2018-08-27 base.py[line:93] Not Found: /static/admin/css/base.css
2018-08-27 base.py[line:93] Not Found: /static/admin/css/login.css
2018-08-27 base.py[line:93] Not Found: /static/admin/css/responsive.css
2018-08-27 exception.py[line:118] Internal Server Error: /admin/YunHui/user/
Traceback (most recent call last):
  File "C:\Users\x86\AppData\Local\Programs\Python\Python36\lib\site-packages\django\db\models\options.py", line 566, in get_field
    return self.fields_map[field_name]
KeyError: 'tieba_num'

During handling of the above exception, another exception occurred:

Traceback (most recent call last):
  File "C:\Users\x86\AppData\Local\Programs\Python\Python36\lib\site-packages\django\contrib\admin\utils.py", line 276, in lookup_field
    f = _get_non_gfk_field(opts, name)
  File "C:\Users\x86\AppData\Local\Programs\Python\Python36\lib\site-packages\django\contrib\admin\utils.py", line 307, in _get_non_gfk_field
    field = opts.get_field(name)
  File "C:\Users\x86\AppData\Local\Programs\Python\Python36\lib\site-packages\django\db\models\options.py", line 568, in get_field
    raise FieldDoesNotExist("%s has no field named '%s'" % (self.object_name, field_name))
django.core.exceptions.FieldDoesNotExist: User has no field named 'tieba_num'

During handling of the above exception, another exception occurred:

Traceback (most recent call last):
  File "C:\Users\x86\AppData\Local\Programs\Python\Python36\lib\site-packages\django\core\handlers\exception.py", line 35, in inner
    response = get_response(request)
  File "C:\Users\x86\AppData\Local\Programs\Python\Python36\lib\site-packages\django\core\handlers\base.py", line 158, in _get_response
    response = self.process_exception_by_middleware(e, request)
  File "C:\Users\x86\AppData\Local\Programs\Python\Python36\lib\site-packages\django\core\handlers\base.py", line 156, in _get_response
    response = response.render()
  File "C:\Users\x86\AppData\Local\Programs\Python\Python36\lib\site-packages\django\template\response.py", line 106, in render
    self.content = self.rendered_content
  File "C:\Users\x86\AppData\Local\Programs\Python\Python36\lib\site-packages\django\template\response.py", line 83, in rendered_content
    content = template.render(context, self._request)
  File "C:\Users\x86\AppData\Local\Programs\Python\Python36\lib\site-packages\django\template\backends\django.py", line 61, in render
    return self.template.render(context)
  File "C:\Users\x86\AppData\Local\Programs\Python\Python36\lib\site-packages\django\template\base.py", line 175, in render
    return self._render(context)
  File "C:\Users\x86\AppData\Local\Programs\Python\Python36\lib\site-packages\django\template\base.py", line 167, in _render
    return self.nodelist.render(context)
  File "C:\Users\x86\AppData\Local\Programs\Python\Python36\lib\site-packages\django\template\base.py", line 943, in render
    bit = node.render_annotated(context)
  File "C:\Users\x86\AppData\Local\Programs\Python\Python36\lib\site-packages\django\template\base.py", line 910, in render_annotated
    return self.render(context)
  File "C:\Users\x86\AppData\Local\Programs\Python\Python36\lib\site-packages\django\template\loader_tags.py", line 155, in render
    return compiled_parent._render(context)
  File "C:\Users\x86\AppData\Local\Programs\Python\Python36\lib\site-packages\django\template\base.py", line 167, in _render
    return self.nodelist.render(context)
  File "C:\Users\x86\AppData\Local\Programs\Python\Python36\lib\site-packages\django\template\base.py", line 943, in render
    bit = node.render_annotated(context)
  File "C:\Users\x86\AppData\Local\Programs\Python\Python36\lib\site-packages\django\template\base.py", line 910, in render_annotated
    return self.render(context)
  File "C:\Users\x86\AppData\Local\Programs\Python\Python36\lib\site-packages\django\template\loader_tags.py", line 155, in render
    return compiled_parent._render(context)
  File "C:\Users\x86\AppData\Local\Programs\Python\Python36\lib\site-packages\django\template\base.py", line 167, in _render
    return self.nodelist.render(context)
  File "C:\Users\x86\AppData\Local\Programs\Python\Python36\lib\site-packages\django\template\base.py", line 943, in render
    bit = node.render_annotated(context)
  File "C:\Users\x86\AppData\Local\Programs\Python\Python36\lib\site-packages\django\template\base.py", line 910, in render_annotated
    return self.render(context)
  File "C:\Users\x86\AppData\Local\Programs\Python\Python36\lib\site-packages\django\template\loader_tags.py", line 67, in render
    result = block.nodelist.render(context)
  File "C:\Users\x86\AppData\Local\Programs\Python\Python36\lib\site-packages\django\template\base.py", line 943, in render
    bit = node.render_annotated(context)
  File "C:\Users\x86\AppData\Local\Programs\Python\Python36\lib\site-packages\django\template\base.py", line 910, in render_annotated
    return self.render(context)
  File "C:\Users\x86\AppData\Local\Programs\Python\Python36\lib\site-packages\django\template\loader_tags.py", line 67, in render
    result = block.nodelist.render(context)
  File "C:\Users\x86\AppData\Local\Programs\Python\Python36\lib\site-packages\django\template\base.py", line 943, in render
    bit = node.render_annotated(context)
  File "C:\Users\x86\AppData\Local\Programs\Python\Python36\lib\site-packages\django\template\base.py", line 910, in render_annotated
    return self.render(context)
  File "C:\Users\x86\AppData\Local\Programs\Python\Python36\lib\site-packages\django\template\library.py", line 214, in render
    _dict = self.func(*resolved_args, **resolved_kwargs)
  File "C:\Users\x86\AppData\Local\Programs\Python\Python36\lib\site-packages\django\contrib\admin\templatetags\admin_list.py", line 326, in result_list
    'results': list(results(cl))}
  File "C:\Users\x86\AppData\Local\Programs\Python\Python36\lib\site-packages\django\contrib\admin\templatetags\admin_list.py", line 302, in results
    yield ResultList(None, items_for_result(cl, res, None))
  File "C:\Users\x86\AppData\Local\Programs\Python\Python36\lib\site-packages\django\contrib\admin\templatetags\admin_list.py", line 293, in __init__
    super().__init__(*items)
  File "C:\Users\x86\AppData\Local\Programs\Python\Python36\lib\site-packages\django\contrib\admin\templatetags\admin_list.py", line 212, in items_for_result
    f, attr, value = lookup_field(field_name, result, cl.model_admin)
  File "C:\Users\x86\AppData\Local\Programs\Python\Python36\lib\site-packages\django\contrib\admin\utils.py", line 289, in lookup_field
    value = attr()
  File "C:\Users\x86\Desktop\开发\TiebaProject\YunHui\models.py", line 20, in tieba_num
    return self.tieba_num().all().count()
  File "C:\Users\x86\Desktop\开发\TiebaProject\YunHui\models.py", line 20, in tieba_num
    return self.tieba_num().all().count()
  File "C:\Users\x86\Desktop\开发\TiebaProject\YunHui\models.py", line 20, in tieba_num
    return self.tieba_num().all().count()
  [Previous line repeated 901 more times]
RecursionError: maximum recursion depth exceeded
2018-08-27 exception.py[line:118] Internal Server Error: /admin/YunHui/user/
Traceback (most recent call last):
  File "C:\Users\x86\AppData\Local\Programs\Python\Python36\lib\site-packages\django\db\models\options.py", line 566, in get_field
    return self.fields_map[field_name]
KeyError: 'tieba_num'

During handling of the above exception, another exception occurred:

Traceback (most recent call last):
  File "C:\Users\x86\AppData\Local\Programs\Python\Python36\lib\site-packages\django\contrib\admin\utils.py", line 276, in lookup_field
    f = _get_non_gfk_field(opts, name)
  File "C:\Users\x86\AppData\Local\Programs\Python\Python36\lib\site-packages\django\contrib\admin\utils.py", line 307, in _get_non_gfk_field
    field = opts.get_field(name)
  File "C:\Users\x86\AppData\Local\Programs\Python\Python36\lib\site-packages\django\db\models\options.py", line 568, in get_field
    raise FieldDoesNotExist("%s has no field named '%s'" % (self.object_name, field_name))
django.core.exceptions.FieldDoesNotExist: User has no field named 'tieba_num'

During handling of the above exception, another exception occurred:

Traceback (most recent call last):
  File "C:\Users\x86\AppData\Local\Programs\Python\Python36\lib\site-packages\django\core\handlers\exception.py", line 35, in inner
    response = get_response(request)
  File "C:\Users\x86\AppData\Local\Programs\Python\Python36\lib\site-packages\django\core\handlers\base.py", line 158, in _get_response
    response = self.process_exception_by_middleware(e, request)
  File "C:\Users\x86\AppData\Local\Programs\Python\Python36\lib\site-packages\django\core\handlers\base.py", line 156, in _get_response
    response = response.render()
  File "C:\Users\x86\AppData\Local\Programs\Python\Python36\lib\site-packages\django\template\response.py", line 106, in render
    self.content = self.rendered_content
  File "C:\Users\x86\AppData\Local\Programs\Python\Python36\lib\site-packages\django\template\response.py", line 83, in rendered_content
    content = template.render(context, self._request)
  File "C:\Users\x86\AppData\Local\Programs\Python\Python36\lib\site-packages\django\template\backends\django.py", line 61, in render
    return self.template.render(context)
  File "C:\Users\x86\AppData\Local\Programs\Python\Python36\lib\site-packages\django\template\base.py", line 175, in render
    return self._render(context)
  File "C:\Users\x86\AppData\Local\Programs\Python\Python36\lib\site-packages\django\template\base.py", line 167, in _render
    return self.nodelist.render(context)
  File "C:\Users\x86\AppData\Local\Programs\Python\Python36\lib\site-packages\django\template\base.py", line 943, in render
    bit = node.render_annotated(context)
  File "C:\Users\x86\AppData\Local\Programs\Python\Python36\lib\site-packages\django\template\base.py", line 910, in render_annotated
    return self.render(context)
  File "C:\Users\x86\AppData\Local\Programs\Python\Python36\lib\site-packages\django\template\loader_tags.py", line 155, in render
    return compiled_parent._render(context)
  File "C:\Users\x86\AppData\Local\Programs\Python\Python36\lib\site-packages\django\template\base.py", line 167, in _render
    return self.nodelist.render(context)
  File "C:\Users\x86\AppData\Local\Programs\Python\Python36\lib\site-packages\django\template\base.py", line 943, in render
    bit = node.render_annotated(context)
  File "C:\Users\x86\AppData\Local\Programs\Python\Python36\lib\site-packages\django\template\base.py", line 910, in render_annotated
    return self.render(context)
  File "C:\Users\x86\AppData\Local\Programs\Python\Python36\lib\site-packages\django\template\loader_tags.py", line 155, in render
    return compiled_parent._render(context)
  File "C:\Users\x86\AppData\Local\Programs\Python\Python36\lib\site-packages\django\template\base.py", line 167, in _render
    return self.nodelist.render(context)
  File "C:\Users\x86\AppData\Local\Programs\Python\Python36\lib\site-packages\django\template\base.py", line 943, in render
    bit = node.render_annotated(context)
  File "C:\Users\x86\AppData\Local\Programs\Python\Python36\lib\site-packages\django\template\base.py", line 910, in render_annotated
    return self.render(context)
  File "C:\Users\x86\AppData\Local\Programs\Python\Python36\lib\site-packages\django\template\loader_tags.py", line 67, in render
    result = block.nodelist.render(context)
  File "C:\Users\x86\AppData\Local\Programs\Python\Python36\lib\site-packages\django\template\base.py", line 943, in render
    bit = node.render_annotated(context)
  File "C:\Users\x86\AppData\Local\Programs\Python\Python36\lib\site-packages\django\template\base.py", line 910, in render_annotated
    return self.render(context)
  File "C:\Users\x86\AppData\Local\Programs\Python\Python36\lib\site-packages\django\template\loader_tags.py", line 67, in render
    result = block.nodelist.render(context)
  File "C:\Users\x86\AppData\Local\Programs\Python\Python36\lib\site-packages\django\template\base.py", line 943, in render
    bit = node.render_annotated(context)
  File "C:\Users\x86\AppData\Local\Programs\Python\Python36\lib\site-packages\django\template\base.py", line 910, in render_annotated
    return self.render(context)
  File "C:\Users\x86\AppData\Local\Programs\Python\Python36\lib\site-packages\django\template\library.py", line 214, in render
    _dict = self.func(*resolved_args, **resolved_kwargs)
  File "C:\Users\x86\AppData\Local\Programs\Python\Python36\lib\site-packages\django\contrib\admin\templatetags\admin_list.py", line 326, in result_list
    'results': list(results(cl))}
  File "C:\Users\x86\AppData\Local\Programs\Python\Python36\lib\site-packages\django\contrib\admin\templatetags\admin_list.py", line 302, in results
    yield ResultList(None, items_for_result(cl, res, None))
  File "C:\Users\x86\AppData\Local\Programs\Python\Python36\lib\site-packages\django\contrib\admin\templatetags\admin_list.py", line 293, in __init__
    super().__init__(*items)
  File "C:\Users\x86\AppData\Local\Programs\Python\Python36\lib\site-packages\django\contrib\admin\templatetags\admin_list.py", line 212, in items_for_result
    f, attr, value = lookup_field(field_name, result, cl.model_admin)
  File "C:\Users\x86\AppData\Local\Programs\Python\Python36\lib\site-packages\django\contrib\admin\utils.py", line 289, in lookup_field
    value = attr()
  File "C:\Users\x86\Desktop\开发\TiebaProject\YunHui\models.py", line 20, in tieba_num
    return self.tieba_num().all().count()
  File "C:\Users\x86\Desktop\开发\TiebaProject\YunHui\models.py", line 20, in tieba_num
    return self.tieba_num().all().count()
  File "C:\Users\x86\Desktop\开发\TiebaProject\YunHui\models.py", line 20, in tieba_num
    return self.tieba_num().all().count()
  [Previous line repeated 901 more times]
RecursionError: maximum recursion depth exceeded
2018-08-27 exception.py[line:118] Internal Server Error: /admin/YunHui/user/
Traceback (most recent call last):
  File "C:\Users\x86\AppData\Local\Programs\Python\Python36\lib\site-packages\django\db\models\options.py", line 566, in get_field
    return self.fields_map[field_name]
KeyError: '签到'

During handling of the above exception, another exception occurred:

Traceback (most recent call last):
  File "C:\Users\x86\AppData\Local\Programs\Python\Python36\lib\site-packages\django\contrib\admin\utils.py", line 276, in lookup_field
    f = _get_non_gfk_field(opts, name)
  File "C:\Users\x86\AppData\Local\Programs\Python\Python36\lib\site-packages\django\contrib\admin\utils.py", line 307, in _get_non_gfk_field
    field = opts.get_field(name)
  File "C:\Users\x86\AppData\Local\Programs\Python\Python36\lib\site-packages\django\db\models\options.py", line 568, in get_field
    raise FieldDoesNotExist("%s has no field named '%s'" % (self.object_name, field_name))
django.core.exceptions.FieldDoesNotExist: User has no field named '签到'

During handling of the above exception, another exception occurred:

Traceback (most recent call last):
  File "C:\Users\x86\AppData\Local\Programs\Python\Python36\lib\site-packages\django\core\handlers\exception.py", line 35, in inner
    response = get_response(request)
  File "C:\Users\x86\AppData\Local\Programs\Python\Python36\lib\site-packages\django\core\handlers\base.py", line 158, in _get_response
    response = self.process_exception_by_middleware(e, request)
  File "C:\Users\x86\AppData\Local\Programs\Python\Python36\lib\site-packages\django\core\handlers\base.py", line 156, in _get_response
    response = response.render()
  File "C:\Users\x86\AppData\Local\Programs\Python\Python36\lib\site-packages\django\template\response.py", line 106, in render
    self.content = self.rendered_content
  File "C:\Users\x86\AppData\Local\Programs\Python\Python36\lib\site-packages\django\template\response.py", line 83, in rendered_content
    content = template.render(context, self._request)
  File "C:\Users\x86\AppData\Local\Programs\Python\Python36\lib\site-packages\django\template\backends\django.py", line 61, in render
    return self.template.render(context)
  File "C:\Users\x86\AppData\Local\Programs\Python\Python36\lib\site-packages\django\template\base.py", line 175, in render
    return self._render(context)
  File "C:\Users\x86\AppData\Local\Programs\Python\Python36\lib\site-packages\django\template\base.py", line 167, in _render
    return self.nodelist.render(context)
  File "C:\Users\x86\AppData\Local\Programs\Python\Python36\lib\site-packages\django\template\base.py", line 943, in render
    bit = node.render_annotated(context)
  File "C:\Users\x86\AppData\Local\Programs\Python\Python36\lib\site-packages\django\template\base.py", line 910, in render_annotated
    return self.render(context)
  File "C:\Users\x86\AppData\Local\Programs\Python\Python36\lib\site-packages\django\template\loader_tags.py", line 155, in render
    return compiled_parent._render(context)
  File "C:\Users\x86\AppData\Local\Programs\Python\Python36\lib\site-packages\django\template\base.py", line 167, in _render
    return self.nodelist.render(context)
  File "C:\Users\x86\AppData\Local\Programs\Python\Python36\lib\site-packages\django\template\base.py", line 943, in render
    bit = node.render_annotated(context)
  File "C:\Users\x86\AppData\Local\Programs\Python\Python36\lib\site-packages\django\template\base.py", line 910, in render_annotated
    return self.render(context)
  File "C:\Users\x86\AppData\Local\Programs\Python\Python36\lib\site-packages\django\template\loader_tags.py", line 155, in render
    return compiled_parent._render(context)
  File "C:\Users\x86\AppData\Local\Programs\Python\Python36\lib\site-packages\django\template\base.py", line 167, in _render
    return self.nodelist.render(context)
  File "C:\Users\x86\AppData\Local\Programs\Python\Python36\lib\site-packages\django\template\base.py", line 943, in render
    bit = node.render_annotated(context)
  File "C:\Users\x86\AppData\Local\Programs\Python\Python36\lib\site-packages\django\template\base.py", line 910, in render_annotated
    return self.render(context)
  File "C:\Users\x86\AppData\Local\Programs\Python\Python36\lib\site-packages\django\template\loader_tags.py", line 67, in render
    result = block.nodelist.render(context)
  File "C:\Users\x86\AppData\Local\Programs\Python\Python36\lib\site-packages\django\template\base.py", line 943, in render
    bit = node.render_annotated(context)
  File "C:\Users\x86\AppData\Local\Programs\Python\Python36\lib\site-packages\django\template\base.py", line 910, in render_annotated
    return self.render(context)
  File "C:\Users\x86\AppData\Local\Programs\Python\Python36\lib\site-packages\django\template\loader_tags.py", line 67, in render
    result = block.nodelist.render(context)
  File "C:\Users\x86\AppData\Local\Programs\Python\Python36\lib\site-packages\django\template\base.py", line 943, in render
    bit = node.render_annotated(context)
  File "C:\Users\x86\AppData\Local\Programs\Python\Python36\lib\site-packages\django\template\base.py", line 910, in render_annotated
    return self.render(context)
  File "C:\Users\x86\AppData\Local\Programs\Python\Python36\lib\site-packages\django\template\library.py", line 214, in render
    _dict = self.func(*resolved_args, **resolved_kwargs)
  File "C:\Users\x86\AppData\Local\Programs\Python\Python36\lib\site-packages\django\contrib\admin\templatetags\admin_list.py", line 326, in result_list
    'results': list(results(cl))}
  File "C:\Users\x86\AppData\Local\Programs\Python\Python36\lib\site-packages\django\contrib\admin\templatetags\admin_list.py", line 302, in results
    yield ResultList(None, items_for_result(cl, res, None))
  File "C:\Users\x86\AppData\Local\Programs\Python\Python36\lib\site-packages\django\contrib\admin\templatetags\admin_list.py", line 293, in __init__
    super().__init__(*items)
  File "C:\Users\x86\AppData\Local\Programs\Python\Python36\lib\site-packages\django\contrib\admin\templatetags\admin_list.py", line 212, in items_for_result
    f, attr, value = lookup_field(field_name, result, cl.model_admin)
  File "C:\Users\x86\AppData\Local\Programs\Python\Python36\lib\site-packages\django\contrib\admin\utils.py", line 289, in lookup_field
    value = attr()
  File "C:\Users\x86\Desktop\开发\TiebaProject\YunHui\models.py", line 26, in 签到
    return self.已签到()+'/'+self.未签到()
TypeError: unsupported operand type(s) for +: 'int' and 'str'
2018-08-27 exception.py[line:118] Internal Server Error: /test/
Traceback (most recent call last):
  File "C:\Users\x86\AppData\Local\Programs\Python\Python36\lib\site-packages\pymysql\connections.py", line 582, in connect
    **kwargs)
  File "C:\Users\x86\AppData\Local\Programs\Python\Python36\lib\socket.py", line 724, in create_connection
    raise err
  File "C:\Users\x86\AppData\Local\Programs\Python\Python36\lib\socket.py", line 713, in create_connection
    sock.connect(sa)
socket.timeout: timed out

During handling of the above exception, another exception occurred:

Traceback (most recent call last):
  File "C:\Users\x86\AppData\Local\Programs\Python\Python36\lib\site-packages\django\db\backends\base\base.py", line 216, in ensure_connection
    self.connect()
  File "C:\Users\x86\AppData\Local\Programs\Python\Python36\lib\site-packages\django\db\backends\base\base.py", line 194, in connect
    self.connection = self.get_new_connection(conn_params)
  File "C:\Users\x86\AppData\Local\Programs\Python\Python36\lib\site-packages\django\db\backends\mysql\base.py", line 234, in get_new_connection
    return Database.connect(**conn_params)
  File "C:\Users\x86\AppData\Local\Programs\Python\Python36\lib\site-packages\pymysql\__init__.py", line 94, in Connect
    return Connection(*args, **kwargs)
  File "C:\Users\x86\AppData\Local\Programs\Python\Python36\lib\site-packages\pymysql\connections.py", line 327, in __init__
    self.connect()
  File "C:\Users\x86\AppData\Local\Programs\Python\Python36\lib\site-packages\pymysql\connections.py", line 629, in connect
    raise exc
pymysql.err.OperationalError: (2003, "Can't connect to MySQL server on '139.199.1.171' (timed out)")

The above exception was the direct cause of the following exception:

Traceback (most recent call last):
  File "C:\Users\x86\AppData\Local\Programs\Python\Python36\lib\site-packages\django\core\handlers\exception.py", line 35, in inner
    response = get_response(request)
  File "C:\Users\x86\AppData\Local\Programs\Python\Python36\lib\site-packages\django\core\handlers\base.py", line 128, in _get_response
    response = self.process_exception_by_middleware(e, request)
  File "C:\Users\x86\AppData\Local\Programs\Python\Python36\lib\site-packages\django\core\handlers\base.py", line 126, in _get_response
    response = wrapped_callback(request, *callback_args, **callback_kwargs)
  File "C:\Users\x86\Desktop\开发\TiebaProject\YunHui\views.py", line 17, in test
    u = User.objects.get(username='旬阳城管')
  File "C:\Users\x86\AppData\Local\Programs\Python\Python36\lib\site-packages\django\db\models\manager.py", line 82, in manager_method
    return getattr(self.get_queryset(), name)(*args, **kwargs)
  File "C:\Users\x86\AppData\Local\Programs\Python\Python36\lib\site-packages\django\db\models\query.py", line 397, in get
    num = len(clone)
  File "C:\Users\x86\AppData\Local\Programs\Python\Python36\lib\site-packages\django\db\models\query.py", line 254, in __len__
    self._fetch_all()
  File "C:\Users\x86\AppData\Local\Programs\Python\Python36\lib\site-packages\django\db\models\query.py", line 1179, in _fetch_all
    self._result_cache = list(self._iterable_class(self))
  File "C:\Users\x86\AppData\Local\Programs\Python\Python36\lib\site-packages\django\db\models\query.py", line 53, in __iter__
    results = compiler.execute_sql(chunked_fetch=self.chunked_fetch, chunk_size=self.chunk_size)
  File "C:\Users\x86\AppData\Local\Programs\Python\Python36\lib\site-packages\django\db\models\sql\compiler.py", line 1055, in execute_sql
    sql, params = self.as_sql()
  File "C:\Users\x86\AppData\Local\Programs\Python\Python36\lib\site-packages\django\db\models\sql\compiler.py", line 461, in as_sql
    where, w_params = self.compile(self.where) if self.where is not None else ("", [])
  File "C:\Users\x86\AppData\Local\Programs\Python\Python36\lib\site-packages\django\db\models\sql\compiler.py", line 393, in compile
    sql, params = node.as_sql(self, self.connection)
  File "C:\Users\x86\AppData\Local\Programs\Python\Python36\lib\site-packages\django\db\models\sql\where.py", line 80, in as_sql
    sql, params = compiler.compile(child)
  File "C:\Users\x86\AppData\Local\Programs\Python\Python36\lib\site-packages\django\db\models\sql\compiler.py", line 393, in compile
    sql, params = node.as_sql(self, self.connection)
  File "C:\Users\x86\AppData\Local\Programs\Python\Python36\lib\site-packages\django\db\models\lookups.py", line 160, in as_sql
    lhs_sql, params = self.process_lhs(compiler, connection)
  File "C:\Users\x86\AppData\Local\Programs\Python\Python36\lib\site-packages\django\db\models\lookups.py", line 153, in process_lhs
    db_type = self.lhs.output_field.db_type(connection=connection)
  File "C:\Users\x86\AppData\Local\Programs\Python\Python36\lib\site-packages\django\db\models\fields\__init__.py", line 648, in db_type
    return connection.data_types[self.get_internal_type()] % data
  File "C:\Users\x86\AppData\Local\Programs\Python\Python36\lib\site-packages\django\utils\functional.py", line 36, in __get__
    res = instance.__dict__[self.name] = self.func(instance)
  File "C:\Users\x86\AppData\Local\Programs\Python\Python36\lib\site-packages\django\db\backends\mysql\base.py", line 133, in data_types
    if self.features.supports_microsecond_precision:
  File "C:\Users\x86\AppData\Local\Programs\Python\Python36\lib\site-packages\django\utils\functional.py", line 36, in __get__
    res = instance.__dict__[self.name] = self.func(instance)
  File "C:\Users\x86\AppData\Local\Programs\Python\Python36\lib\site-packages\django\db\backends\mysql\features.py", line 65, in supports_microsecond_precision
    return self.connection.mysql_version >= (5, 6, 4)
  File "C:\Users\x86\AppData\Local\Programs\Python\Python36\lib\site-packages\django\utils\functional.py", line 36, in __get__
    res = instance.__dict__[self.name] = self.func(instance)
  File "C:\Users\x86\AppData\Local\Programs\Python\Python36\lib\site-packages\django\db\backends\mysql\base.py", line 343, in mysql_version
    with self.temporary_connection() as cursor:
  File "C:\Users\x86\AppData\Local\Programs\Python\Python36\lib\contextlib.py", line 81, in __enter__
    return next(self.gen)
  File "C:\Users\x86\AppData\Local\Programs\Python\Python36\lib\site-packages\django\db\backends\base\base.py", line 576, in temporary_connection
    cursor = self.cursor()
  File "C:\Users\x86\AppData\Local\Programs\Python\Python36\lib\site-packages\django\db\backends\base\base.py", line 255, in cursor
    return self._cursor()
  File "C:\Users\x86\AppData\Local\Programs\Python\Python36\lib\site-packages\django\db\backends\base\base.py", line 232, in _cursor
    self.ensure_connection()
  File "C:\Users\x86\AppData\Local\Programs\Python\Python36\lib\site-packages\django\db\backends\base\base.py", line 216, in ensure_connection
    self.connect()
  File "C:\Users\x86\AppData\Local\Programs\Python\Python36\lib\site-packages\django\db\utils.py", line 89, in __exit__
    raise dj_exc_value.with_traceback(traceback) from exc_value
  File "C:\Users\x86\AppData\Local\Programs\Python\Python36\lib\site-packages\django\db\backends\base\base.py", line 216, in ensure_connection
    self.connect()
  File "C:\Users\x86\AppData\Local\Programs\Python\Python36\lib\site-packages\django\db\backends\base\base.py", line 194, in connect
    self.connection = self.get_new_connection(conn_params)
  File "C:\Users\x86\AppData\Local\Programs\Python\Python36\lib\site-packages\django\db\backends\mysql\base.py", line 234, in get_new_connection
    return Database.connect(**conn_params)
  File "C:\Users\x86\AppData\Local\Programs\Python\Python36\lib\site-packages\pymysql\__init__.py", line 94, in Connect
    return Connection(*args, **kwargs)
  File "C:\Users\x86\AppData\Local\Programs\Python\Python36\lib\site-packages\pymysql\connections.py", line 327, in __init__
    self.connect()
  File "C:\Users\x86\AppData\Local\Programs\Python\Python36\lib\site-packages\pymysql\connections.py", line 629, in connect
    raise exc
django.db.utils.OperationalError: (2003, "Can't connect to MySQL server on '139.199.1.171' (timed out)")
2018-08-27 exception.py[line:118] Internal Server Error: /test/
Traceback (most recent call last):
  File "C:\Users\x86\AppData\Local\Programs\Python\Python36\lib\site-packages\django\core\handlers\exception.py", line 35, in inner
    response = get_response(request)
  File "C:\Users\x86\AppData\Local\Programs\Python\Python36\lib\site-packages\django\core\handlers\base.py", line 139, in _get_response
    "returned None instead." % (callback.__module__, view_name)
ValueError: The view YunHui.views.test didn't return an HttpResponse object. It returned None instead.
2018-08-27 exception.py[line:118] Internal Server Error: /test/
Traceback (most recent call last):
  File "C:\Users\x86\AppData\Local\Programs\Python\Python36\lib\site-packages\django\core\handlers\exception.py", line 35, in inner
    response = get_response(request)
  File "C:\Users\x86\AppData\Local\Programs\Python\Python36\lib\site-packages\django\core\handlers\base.py", line 139, in _get_response
    "returned None instead." % (callback.__module__, view_name)
ValueError: The view YunHui.views.test didn't return an HttpResponse object. It returned None instead.
